Workbook

Sheet Sheet1
A1: 1本ごとの推移（9ロット）
AM3: =AVERAGE(AL5:AL9) -> 292.5 | AQ3: =AVERAGE(AP5:AP9) -> 294.14 | AU3: =AVERAGE(AT5:AT9) -> 293.02 | AY3: =AVERAGE(AX5:AX9) -> 293.84 | BC3: =AVERAGE(BB5:BB9) -> 293.74 | BG3: =AVERAGE(BF5:BF9) -> 293.62
A4: 測定順 | B4: ロット1 | C4: 基準 | D4: 上限 | E4: 下限 | F4: ロット2 | G4: 基準 | H4: 上限 | I4: 下限 | J4: ロット3 | K4: 基準 | L4: 上限 | M4: 下限 | N4: ロット4 | O4: 基準 | P4: 上限 | Q4: 下限 | R4: ロット5 | S4: 基準 | T4: 上限 | U4: 下限 | V4: ロット6 | W4: 基準 | X4: 上限 | Y4: 下限 | Z4: ロット7 | AA4: 基準 | AB4: 上限 | AC4: 下限 | AD4: ロット8 | AE4: 基準 | AF4: 上限 | AG4: 下限 | AH4: ロット9 | AI4: 基準 | AJ4: 上限 | AK4: 下限 | AL4: ロット10 | AM4: 基準 | AN4: 上限 | AO4: 下限 | AP4: ロット11 | AQ4: 基準 | AR4: 上限 | AS4: 下限 | AT4: ロット12 | AU4: 基準 | AV4: 上限 | AW4: 下限 | AX4: ロット13 | AY4: 基準 | AZ4: 上限 | BA4: 下限 | BB4: ロット14 | BC4: 基準 | BD4: 上限 | BE4: 下限 | BF4: ロット15 | BG4: 基準 | BH4: 上限 | BI4: 下限
A5: 1 | B5: =IF([1]生データ_製品!$F5="生産品",[1]生データ_製品!$D5,NA()) -> 294.3 | C5: 294.4 | D5: 295.8 | E5: 293 | F5: =IF([1]生データ_製品!$F2464="生産品",[1]生データ_製品!$D2464,NA()) -> 294.7 | G5: 295.2 | H5: 296.64 | I5: 293.8 | J5: =IF([1]生データ_製品!$F5033="生産品",[1]生データ_製品!$D5033,NA()) -> 294.1 | K5: 294.2 | L5: 295.64 | M5: 292.8 | N5: =IF([1]生データ_製品!$F7502="生産品",[1]生データ_製品!$D7502,NA()) -> 295.2 | O5: 295.4 | P5: 296.8 | Q5: 294 | R5: =IF([1]生データ_製品!$F10116="生産品",[1]生データ_製品!$D10116,NA()) -> 292.7 | S5: 292.5 | T5: 293.9 | U5: 291.1 | V5: =IF([1]生データ_製品!$F12614="生産品",[1]生データ_製品!$D12614,NA()) -> 291.5 | W5: 292.3 | X5: 293.7 | Y5: 290.9 | Z5: =IF([1]生データ_製品!$F15324="生産品",[1]生データ_製品!$D15324,NA()) -> 293.4 | AA5: 294.2 | AB5: 295.6 | AC5: 292.8 | AD5: =IF([1]生データ_製品!$F17923="生産品",[1]生データ_製品!$D17923,NA()) -> 295 | AE5: 295.2 | AF5: 296.6 | AG5: 293.8 | AH5: =IF([1]生データ_製品!$F20516="生産品",[1]生データ_製品!$D20516,NA()) -> 295.4 | AI5: 295.8 | AJ5: 297.2 | AK5: 294.4 | AL5: =IF([1]生データ_製品!$F23064="生産品",[1]生データ_製品!$D23064,NA()) -> 292.7 | AM5: 292.5 | AN5: 293.9 | AO5: 291.1 | AP5: =IF([1]生データ_製品!$F25580="生産品",[1]生データ_製品!$D25580,NA()) -> 294.1 | AQ5: 294.1 | AR5: 295.5 | AS5: 292.7 | AT5: =IF([1]生データ_製品!$F28105="生産品",[1]生データ_製品!$D28105,NA()) -> 293.3 | AU5: 293 | AV5: 294.4 | AW5: 291.6 | AX5: =IF([1]生データ_製品!$F30756="生産品",[1]生データ_製品!$D30756,NA()) -> 293.9 | AY5: 293.8 | AZ5: 295.2 | BA5: 292.4 | BB5: =IF([1]生データ_製品!$F33253="生産品",[1]生データ_製品!$D33253,NA()) -> 293.8 | BC5: 293.7 | BD5: 295.1 | BE5: 292.3 | BF5: =IF([1]生データ_製品!$F35706="生産品",[1]生データ_製品!$D35706,NA()) -> 293.3 | BG5: 293.6 | BH5: 295 | BI5: 292.2
A6: 2 | B6: =IF([1]生データ_製品!$F6="生産品",[1]生データ_製品!$D6,NA()) -> 294.3 | C6: 294.4 | D6: 295.8 | E6: 293 | F6: =IF([1]生データ_製品!$F2465="生産品",[1]生データ_製品!$D2465,NA()) -> 295.3 | G6: 295.2 | H6: 296.64 | I6: 293.8 | J6: =IF([1]生データ_製品!$F5034="生産品",[1]生データ_製品!$D5034,NA()) -> 294.7 | K6: 294.2 | L6: 295.64 | M6: 292.8 | N6: =IF([1]生データ_製品!$F7503="生産品",[1]生データ_製品!$D7503,NA()) -> 295.4 | O6: 295.4 | P6: 296.8 | Q6: 294 | R6: =IF([1]生データ_製品!$F10117="生産品",[1]生データ_製品!$D10117,NA()) -> 292.6 | S6: 292.5 | T6: 293.9 | U6: 291.1 | V6: =IF([1]生データ_製品!$F12615="生産品",[1]生データ_製品!$D12615,NA()) -> 291.7 | W6: 292.3 | X6: 293.7 | Y6: 290.9 | Z6: =IF([1]生データ_製品!$F15325="生産品",[1]生データ_製品!$D15325,NA()) -> 294.8 | AA6: 294.2 | AB6: 295.6 | AC6: 292.8 | AD6: =IF([1]生データ_製品!$F17924="生産品",[1]生データ_製品!$D17924,NA()) -> 294.9 | AE6: 295.2 | AF6: 296.6 | AG6: 293.8 | AH6: =IF([1]生データ_製品!$F20517="生産品",[1]生データ_製品!$D20517,NA()) -> 296.2 | AI6: 295.8 | AJ6: 297.2 | AK6: 294.4 | AL6: =IF([1]生データ_製品!$F23065="生産品",[1]生データ_製品!$D23065,NA()) -> 291.9 | AM6: 292.5 | AN6: 293.9 | AO6: 291.1 | AP6: =IF([1]生データ_製品!$F25581="生産品",[1]生データ_製品!$D25581,NA()) -> 293.8 | AQ6: 294.1 | AR6: 295.5 | AS6: 292.7 | AT6: =IF([1]生データ_製品!$F28106="生産品",[1]生データ_製品!$D28106,NA()) -> 293 | AU6: 293 | AV6: 294.4 | AW6: 291.6 | AX6: =IF([1]生データ_製品!$F30757="生産品",[1]生データ_製品!$D30757,NA()) -> 292.8 | AY6: 293.8 | AZ6: 295.2 | BA6: 292.4 | BB6: =IF([1]生データ_製品!$F33254="生産品",[1]生データ_製品!$D33254,NA()) -> 292.9 | BC6: 293.7 | BD6: 295.1 | BE6: 292.3 | BF6: =IF([1]生データ_製品!$F35707="生産品",[1]生データ_製品!$D35707,NA()) -> 293.6 | BG6: 293.6 | BH6: 295 | BI6: 292.2
A7: 3 | B7: =IF([1]生データ_製品!$F7="生産品",[1]生データ_製品!$D7,NA()) -> 294.7 | C7: 294.4 | D7: 295.8 | E7: 293 | F7: =IF([1]生データ_製品!$F2466="生産品",[1]生データ_製品!$D2466,NA()) -> 294.9 | G7: 295.2 | H7: 296.64 | I7: 293.8 | J7: =IF([1]生データ_製品!$F5035="生産品",[1]生データ_製品!$D5035,NA()) -> 294.1 | K7: 294.2 | L7: 295.64 | M7: 292.8 | N7: =IF([1]生データ_製品!$F7504="生産品",[1]生データ_製品!$D7504,NA()) -> 295.2 | O7: 295.4 | P7: 296.8 | Q7: 294 | R7: =IF([1]生データ_製品!$F10118="生産品",[1]生データ_製品!$D10118,NA()) -> 292.3 | S7: 292.5 | T7: 293.9 | U7: 291.1 | V7: =IF([1]生データ_製品!$F12616="生産品",[1]生データ_製品!$D12616,NA()) -> 292.8 | W7: 292.3 | X7: 293.7 | Y7: 290.9 | Z7: =IF([1]生データ_製品!$F15326="生産品",[1]生データ_製品!$D15326,NA()) -> 294.6 | AA7: 294.2 | AB7: 295.6 | AC7: 292.8 | AD7: =IF([1]生データ_製品!$F17925="生産品",[1]生データ_製品!$D17925,NA()) -> 295.1 | AE7: 295.2 | AF7: 296.6 | AG7: 293.8 | AH7: =IF([1]生データ_製品!$F20518="生産品",[1]生データ_製品!$D20518,NA()) -> 295.2 | AI7: 295.8 | AJ7: 297.2 | AK7: 294.4 | AL7: =IF([1]生データ_製品!$F23066="生産品",[1]生データ_製品!$D23066,NA()) -> 292.1 | AM7: 292.5 | AN7: 293.9 | AO7: 291.1 | AP7: =IF([1]生データ_製品!$F25582="生産品",[1]生データ_製品!$D25582,NA()) -> 293.9 | AQ7: 294.1 | AR7: 295.5 | AS7: 292.7 | AT7: =IF([1]生データ_製品!$F28107="生産品",[1]生データ_製品!$D28107,NA()) -> 292.7 | AU7: 293 | AV7: 294.4 | AW7: 291.6 | AX7: =IF([1]生データ_製品!$F30758="生産品",[1]生データ_製品!$D30758,NA()) -> 295 | AY7: 293.8 | AZ7: 295.2 | BA7: 292.4 | BB7: =IF([1]生データ_製品!$F33255="生産品",[1]生データ_製品!$D33255,NA()) -> 294 | BC7: 293.7 | BD7: 295.1 | BE7: 292.3 | BF7: =IF([1]生データ_製品!$F35708="生産品",[1]生データ_製品!$D35708,NA()) -> 293.3 | BG7: 293.6 | BH7: 295 | BI7: 292.2
A8: 4 | B8: =IF([1]生データ_製品!$F8="生産品",[1]生データ_製品!$D8,NA()) -> 294.3 | C8: 294.4 | D8: 295.8 | E8: 293 | F8: =IF([1]生データ_製品!$F2467="生産品",[1]生データ_製品!$D2467,NA()) -> 295.7 | G8: 295.2 | H8: 296.64 | I8: 293.8 | J8: =IF([1]生データ_製品!$F5036="生産品",[1]生データ_製品!$D5036,NA()) -> 293.9 | K8: 294.2 | L8: 295.64 | M8: 292.8 | N8: =IF([1]生データ_製品!$F7505="生産品",[1]生データ_製品!$D7505,NA()) -> 295.6 | O8: 295.4 | P8: 296.8 | Q8: 294 | R8: =IF([1]生データ_製品!$F10119="生産品",[1]生データ_製品!$D10119,NA()) -> 292.4 | S8: 292.5 | T8: 293.9 | U8: 291.1 | V8: =IF([1]生データ_製品!$F12617="生産品",[1]生データ_製品!$D12617,NA()) -> 293.1 | W8: 292.3 | X8: 293.7 | Y8: 290.9 | Z8: =IF([1]生データ_製品!$F15327="生産品",[1]生データ_製品!$D15327,NA()) -> 293.7 | AA8: 294.2 | AB8: 295.6 | AC8: 292.8 | AD8: =IF([1]生データ_製品!$F17926="生産品",[1]生データ_製品!$D17926,NA()) -> 296 | AE8: 295.2 | AF8: 296.6 | AG8: 293.8 | AH8: =IF([1]生データ_製品!$F20519="生産品",[1]生データ_製品!$D20519,NA()) -> 295.9 | AI8: 295.8 | AJ8: 297.2 | AK8: 294.4 | AL8: =IF([1]生データ_製品!$F23067="生産品",[1]生データ_製品!$D23067,NA()) -> 293.3 | AM8: 292.5 | AN8: 293.9 | AO8: 291.1 | AP8: =IF([1]生データ_製品!$F25583="生産品",[1]生データ_製品!$D25583,NA()) -> 294.1 | AQ8: 294.1 | AR8: 295.5 | AS8: 292.7 | AT8: =IF([1]生データ_製品!$F28108="生産品",[1]生データ_製品!$D28108,NA()) -> 293.2 | AU8: 293 | AV8: 294.4 | AW8: 291.6 | AX8: =IF([1]生データ_製品!$F30759="生産品",[1]生データ_製品!$D30759,NA()) -> 293.6 | AY8: 293.8 | AZ8: 295.2 | BA8: 292.4 | BB8: =IF([1]生データ_製品!$F33256="生産品",[1]生データ_製品!$D33256,NA()) -> 294.3 | BC8: 293.7 | BD8: 295.1 | BE8: 292.3 | BF8: =IF([1]生データ_製品!$F35709="生産品",[1]生データ_製品!$D35709,NA()) -> 293.9 | BG8: 293.6 | BH8: 295 | BI8: 292.2
A9: 5 | B9: =IF([1]生データ_製品!$F9="生産品",[1]生データ_製品!$D9,NA()) -> 294.5 | C9: 294.4 | D9: 295.8 | E9: 293 | F9: =IF([1]生データ_製品!$F2468="生産品",[1]生データ_製品!$D2468,NA()) -> 295.3 | G9: 295.2 | H9: 296.64 | I9: 293.8 | J9: =IF([1]生データ_製品!$F5037="生産品",[1]生データ_製品!$D5037,NA()) -> 294 | K9: 294.2 | L9: 295.64 | M9: 292.8 | N9: =IF([1]生データ_製品!$F7506="生産品",[1]生データ_製品!$D7506,NA()) -> 295.4 | O9: 295.4 | P9: 296.8 | Q9: 294 | R9: =IF([1]生データ_製品!$F10120="生産品",[1]生データ_製品!$D10120,NA()) -> 292.7 | S9: 292.5 | T9: 293.9 | U9: 291.1 | V9: =IF([1]生データ_製品!$F12618="生産品",[1]生データ_製品!$D12618,NA()) -> 292.3 | W9: 292.3 | X9: 293.7 | Y9: 290.9 | Z9: =IF([1]生データ_製品!$F15328="生産品",[1]生データ_製品!$D15328,NA()) -> 294.5 | AA9: 294.2 | AB9: 295.6 | AC9: 292.8 | AD9: =IF([1]生データ_製品!$F17927="生産品",[1]生データ_製品!$D17927,NA()) -> 295.1 | AE9: 295.2 | AF9: 296.6 | AG9: 293.8 | AH9: =IF([1]生データ_製品!$F20520="生産品",[1]生データ_製品!$D20520,NA()) -> 296.3 | AI9: 295.8 | AJ9: 297.2 | AK9: 294.4 | AL9: =IF([1]生データ_製品!$F23068="生産品",[1]生データ_製品!$D23068,NA()) -> 292.5 | AM9: 292.5 | AN9: 293.9 | AO9: 291.1 | AP9: =IF([1]生データ_製品!$F25584="生産品",[1]生データ_製品!$D25584,NA()) -> 294.8 | AQ9: 294.1 | AR9: 295.5 | AS9: 292.7 | AT9: =IF([1]生データ_製品!$F28109="生産品",[1]生データ_製品!$D28109,NA()) -> 292.9 | AU9: 293 | AV9: 294.4 | AW9: 291.6 | AX9: =IF([1]生データ_製品!$F30760="生産品",[1]生データ_製品!$D30760,NA()) -> 293.9 | AY9: 293.8 | AZ9: 295.2 | BA9: 292.4 | BB9: =IF([1]生データ_製品!$F33257="生産品",[1]生データ_製品!$D33257,NA()) -> 293.7 | BC9: 293.7 | BD9: 295.1 | BE9: 292.3 | BF9: =IF([1]生データ_製品!$F35710="生産品",[1]生データ_製品!$D35710,NA()) -> 294 | BG9: 293.6 | BH9: 295 | BI9: 292.2
A10: 6 | B10: =IF([1]生データ_製品!$F10="生産品",[1]生データ_製品!$D10,NA()) -> #N/A | C10: 294.4 | D10: 295.8 | E10: 293 | F10: =IF([1]生データ_製品!$F2469="生産品",[1]生データ_製品!$D2469,NA()) -> #N/A | G10: 295.2 | H10: 296.64 | I10: 293.8 | J10: =IF([1]生データ_製品!$F5038="生産品",[1]生データ_製品!$D5038,NA()) -> #N/A | K10: 294.2 | L10: 295.64 | M10: 292.8 | N10: =IF([1]生データ_製品!$F7507="生産品",[1]生データ_製品!$D7507,NA()) -> #N/A | O10: 295.4 | P10: 296.8 | Q10: 294 | R10: =IF([1]生データ_製品!$F10121="生産品",[1]生データ_製品!$D10121,NA()) -> #N/A | S10: 292.5 | T10: 293.9 | U10: 291.1 | V10: =IF([1]生データ_製品!$F12619="生産品",[1]生データ_製品!$D12619,NA()) -> 292.8 | W10: 292.3 | X10: 293.7 | Y10: 290.9 | Z10: =IF([1]生データ_製品!$F15329="生産品",[1]生データ_製品!$D15329,NA()) -> #N/A | AA10: 294.2 | AB10: 295.6 | AC10: 292.8 | AD10: =IF([1]生データ_製品!$F17928="生産品",[1]生データ_製品!$D17928,NA()) -> #N/A | AE10: 295.2 | AF10: 296.6 | AG10: 293.8 | AH10: =IF([1]生データ_製品!$F20521="生産品",[1]生データ_製品!$D20521,NA()) -> 296.2 | AI10: 295.8 | AJ10: 297.2 | AK10: 294.4 | AL10: =IF([1]生データ_製品!$F23069="生産品",[1]生データ_製品!$D23069,NA()) -> #N/A | AM10: 292.5 | AN10: 293.9 | AO10: 291.1 | AP10: =IF([1]生データ_製品!$F25585="生産品",[1]生データ_製品!$D25585,NA()) -> #N/A | AQ10: 294.1 | AR10: 295.5 | AS10: 292.7 | AT10: =IF([1]生データ_製品!$F28110="生産品",[1]生データ_製品!$D28110,NA()) -> #N/A | AU10: 293 | AV10: 294.4 | AW10: 291.6 | AX10: =IF([1]生データ_製品!$F30761="生産品",[1]生データ_製品!$D30761,NA()) -> #N/A | AY10: 293.8 | AZ10: 295.2 | BA10: 292.4 | BB10: =IF([1]生データ_製品!$F33258="生産品",[1]生データ_製品!$D33258,NA()) -> #N/A | BC10: 293.7 | BD10: 295.1 | BE10: 292.3 | BF10: =IF([1]生データ_製品!$F35711="生産品",[1]生データ_製品!$D35711,NA()) -> #N/A | BG10: 293.6 | BH10: 295 | BI10: 292.2
A11: 7 | B11: =IF([1]生データ_製品!$F11="生産品",[1]生データ_製品!$D11,NA()) -> 294.7 | C11: 294.4 | D11: 295.8 | E11: 293 | F11: =IF([1]生データ_製品!$F2470="生産品",[1]生データ_製品!$D2470,NA()) -> 295.3 | G11: 295.2 | H11: 296.64 | I11: 293.8 | J11: =IF([1]生データ_製品!$F5039="生産品",[1]生データ_製品!$D5039,NA()) -> 293.9 | K11: 294.2 | L11: 295.64 | M11: 292.8 | N11: =IF([1]生データ_製品!$F7508="生産品",[1]生データ_製品!$D7508,NA()) -> 295.6 | O11: 295.4 | P11: 296.8 | Q11: 294 | R11: =IF([1]生データ_製品!$F10122="生産品",[1]生データ_製品!$D10122,NA()) -> 292.9 | S11: 292.5 | T11: 293.9 | U11: 291.1 | V11: =IF([1]生データ_製品!$F12620="生産品",[1]生データ_製品!$D12620,NA()) -> 291.6 | W11: 292.3 | X11: 293.7 | Y11: 290.9 | Z11: =IF([1]生データ_製品!$F15330="生産品",[1]生データ_製品!$D15330,NA()) -> 293.5 | AA11: 294.2 | AB11: 295.6 | AC11: 292.8 | AD11: =IF([1]生データ_製品!$F17929="生産品",[1]生データ_製品!$D17929,NA()) -> 294.9 | AE11: 295.2 | AF11: 296.6 | AG11: 293.8 | AH11: =IF([1]生データ_製品!$F20522="生産品",[1]生データ_製品!$D20522,NA()) -> 295.8 | AI11: 295.8 | AJ11: 297.2 | AK11: 294.4 | AL11: =IF([1]生データ_製品!$F23070="生産品",[1]生データ_製品!$D23070,NA()) -> 293.4 | AM11: 292.5 | AN11: 293.9 | AO11: 291.1 | AP11: =IF([1]生データ_製品!$F25586="生産品",[1]生データ_製品!$D25586,NA()) -> 294 | AQ11: 294.1 | AR11: 295.5 | AS11: 292.7 | AT11: =IF([1]生データ_製品!$F28111="生産品",[1]生データ_製品!$D28111,NA()) -> 293.3 | AU11: 293 | AV11: 294.4 | AW11: 291.6 | AX11: =IF([1]生データ_製品!$F30762="生産品",[1]生データ_製品!$D30762,NA()) -> 295.1 | AY11: 293.8 | AZ11: 295.2 | BA11: 292.4 | BB11: =IF([1]生データ_製品!$F33259="生産品",[1]生データ_製品!$D33259,NA()) -> 292.8 | BC11: 293.7 | BD11: 295.1 | BE11: 292.3 | BF11: =IF([1]生データ_製品!$F35712="生産品",[1]生データ_製品!$D35712,NA()) -> #N/A | BG11: 293.6 | BH11: 295 | BI11: 292.2
A12: 8 | B12: =IF([1]生データ_製品!$F12="生産品",[1]生データ_製品!$D12,NA()) -> 294.4 | C12: 294.4 | D12: 295.8 | E12: 293 | F12: =IF([1]生データ_製品!$F2471="生産品",[1]生データ_製品!$D2471,NA()) -> 294.8 | G12: 295.2 | H12: 296.64 | I12: 293.8 | J12: =IF([1]生データ_製品!$F5040="生産品",[1]生データ_製品!$D5040,NA()) -> 294.1 | K12: 294.2 | L12: 295.64 | M12: 292.8 | N12: =IF([1]生データ_製品!$F7509="生産品",[1]生データ_製品!$D7509,NA()) -> 295.5 | O12: 295.4 | P12: 296.8 | Q12: 294 | R12: =IF([1]生データ_製品!$F10123="生産品",[1]生データ_製品!$D10123,NA()) -> 292.6 | S12: 292.5 | T12: 293.9 | U12: 291.1 | V12: =IF([1]生データ_製品!$F12621="生産品",[1]生データ_製品!$D12621,NA()) -> 292.3 | W12: 292.3 | X12: 293.7 | Y12: 290.9 | Z12: =IF([1]生データ_製品!$F15331="生産品",[1]生データ_製品!$D15331,NA()) -> 294.8 | AA12: 294.2 | AB12: 295.6 | AC12: 292.8 | AD12: =IF([1]生データ_製品!$F17930="生産品",[1]生データ_製品!$D17930,NA()) -> 295.2 | AE12: 295.2 | AF12: 296.6 | AG12: 293.8 | AH12: =IF([1]生データ_製品!$F20523="生産品",[1]生データ_製品!$D20523,NA()) -> 296.2 | AI12: 295.8 | AJ12: 297.2 | AK12: 294.4 | AL12: =IF([1]生データ_製品!$F23071="生産品",[1]生データ_製品!$D23071,NA()) -> 292.1 | AM12: 292.5 | AN12: 293.9 | AO12: 291.1 | AP12: =IF([1]生データ_製品!$F25587="生産品",[1]生データ_製品!$D25587,NA()) -> #N/A | AQ12: 294.1 | AR12: 295.5 | AS12: 292.7 | AT12: =IF([1]生データ_製品!$F28112="生産品",[1]生データ_製品!$D28112,NA()) -> 293.4 | AU12: 293 | AV12: 294.4 | AW12: 291.6 | AX12: =IF([1]生データ_製品!$F30763="生産品",[1]生データ_製品!$D30763,NA()) -> 292.9 | AY12: 293.8 | AZ12: 295.2 | BA12: 292.4 | BB12: =IF([1]生データ_製品!$F33260="生産品",[1]生データ_製品!$D33260,NA()) -> 293.8 | BC12: 293.7 | BD12: 295.1 | BE12: 292.3 | BF12: =IF([1]生データ_製品!$F35713="生産品",[1]生データ_製品!$D35713,NA()) -> 293.8 | BG12: 293.6 | BH12: 295 | BI12: 292.2
A13: 9 | B13: =IF([1]生データ_製品!$F13="生産品",[1]生データ_製品!$D13,NA()) -> 294.4 | C13: 294.4 | D13: 295.8 | E13: 293 | F13: =IF([1]生データ_製品!$F2472="生産品",[1]生データ_製品!$D2472,NA()) -> 294.9 | G13: 295.2 | H13: 296.64 | I13: 293.8 | J13: =IF([1]生データ_製品!$F5041="生産品",[1]生データ_製品!$D5041,NA()) -> 294.1 | K13: 294.2 | L13: 295.64 | M13: 292.8 | N13: =IF([1]生データ_製品!$F7510="生産品",[1]生データ_製品!$D7510,NA()) -> 295.5 | O13: 295.4 | P13: 296.8 | Q13: 294 | R13: =IF([1]生データ_製品!$F10124="生産品",[1]生データ_製品!$D10124,NA()) -> 292.4 | S13: 292.5 | T13: 293.9 | U13: 291.1 | V13: =IF([1]生データ_製品!$F12622="生産品",[1]生データ_製品!$D12622,NA()) -> 291.4 | W13: 292.3 | X13: 293.7 | Y13: 290.9 | Z13: =IF([1]生データ_製品!$F15332="生産品",[1]生データ_製品!$D15332,NA()) -> 294.7 | AA13: 294.2 | AB13: 295.6 | AC13: 292.8 | AD13: =IF([1]生データ_製品!$F17931="生産品",[1]生データ_製品!$D17931,NA()) -> 294.8 | AE13: 295.2 | AF13: 296.6 | AG13: 293.8 | AH13: =IF([1]生データ_製品!$F20524="生産品",[1]生データ_製品!$D20524,NA()) -> 295.5 | AI13: 295.8 | AJ13: 297.2 | AK13: 294.4 | AL13: =IF([1]生データ_製品!$F23072="生産品",[1]生データ_製品!$D23072,NA()) -> 292.9 | AM13: 292.5 | AN13: 293.9 | AO13: 291.1 | AP13: =IF([1]生データ_製品!$F25588="生産品",[1]生データ_製品!$D25588,NA()) -> 294.1 | AQ13: 294.1 | AR13: 295.5 | AS13: 292.7 | AT13: =IF([1]生データ_製品!$F28113="生産品",[1]生データ_製品!$D28113,NA()) -> 293.1 | AU13: 293 | AV13: 294.4 | AW13: 291.6 | AX13: =IF([1]生データ_製品!$F30764="生産品",[1]生データ_製品!$D30764,NA()) -> 294.3 | AY13: 293.8 | AZ13: 295.2 | BA13: 292.4 | BB13: =IF([1]生データ_製品!$F33261="生産品",[1]生データ_製品!$D33261,NA()) -> 294.2 | BC13: 293.7 | BD13: 295.1 | BE13: 292.3 | BF13: =IF([1]生データ_製品!$F35714="生産品",[1]生データ_製品!$D35714,NA()) -> 293.7 | BG13: 293.6 | BH13: 295 | BI13: 292.2
A14: 10 | B14: =IF([1]生データ_製品!$F14="生産品",[1]生データ_製品!$D14,NA()) -> 294.9 | C14: 294.4 | D14: 295.8 | E14: 293 | F14: =IF([1]生データ_製品!$F2473="生産品",[1]生データ_製品!$D2473,NA()) -> 295.6 | G14: 295.2 | H14: 296.64 | I14: 293.8 | J14: =IF([1]生データ_製品!$F5042="生産品",[1]生データ_製品!$D5042,NA()) -> 294.4 | K14: 294.2 | L14: 295.64 | M14: 292.8 | N14: =IF([1]生データ_製品!$F7511="生産品",[1]生データ_製品!$D7511,NA()) -> 295.1 | O14: 295.4 | P14: 296.8 | Q14: 294 | R14: =IF([1]生データ_製品!$F10125="生産品",[1]生データ_製品!$D10125,NA()) -> 292.4 | S14: 292.5 | T14: 293.9 | U14: 291.1 | V14: =IF([1]生データ_製品!$F12623="生産品",[1]生データ_製品!$D12623,NA()) -> 292.6 | W14: 292.3 | X14: 293.7 | Y14: 290.9 | Z14: =IF([1]生データ_製品!$F15333="生産品",[1]生データ_製品!$D15333,NA()) -> 294.6 | AA14: 294.2 | AB14: 295.6 | AC14: 292.8 | AD14: =IF([1]生データ_製品!$F17932="生産品",[1]生データ_製品!$D17932,NA()) -> 295.2 | AE14: 295.2 | AF14: 296.6 | AG14: 293.8 | AH14: =IF([1]生データ_製品!$F20525="生産品",[1]生データ_製品!$D20525,NA()) -> 295.2 | AI14: 295.8 | AJ14: 297.2 | AK14: 294.4 | AL14: =IF([1]生データ_製品!$F23073="生産品",[1]生データ_製品!$D23073,NA()) -> #N/A | AM14: 292.5 | AN14: 293.9 | AO14: 291.1 | AP14: =IF([1]生データ_製品!$F25589="生産品",[1]生データ_製品!$D25589,NA()) -> 294.7 | AQ14: 294.1 | AR14: 295.5 | AS14: 292.7 | AT14: =IF([1]生データ_製品!$F28114="生産品",[1]生データ_製品!$D28114,NA()) -> 293 | AU14: 293 | AV14: 294.4 | AW14: 291.6 | AX14: =IF([1]生データ_製品!$F30765="生産品",[1]生データ_製品!$D30765,NA()) -> 293.7 | AY14: 293.8 | AZ14: 295.2 | BA14: 292.4 | BB14: =IF([1]生データ_製品!$F33262="生産品",[1]生データ_製品!$D33262,NA()) -> 293.9 | BC14: 293.7 | BD14: 295.1 | BE14: 292.3 | BF14: =IF([1]生データ_製品!$F35715="生産品",[1]生データ_製品!$D35715,NA()) -> 294.1 | BG14: 293.6 | BH14: 295 | BI14: 292.2
A15: 11 | B15: =IF([1]生データ_製品!$F15="生産品",[1]生データ_製品!$D15,NA()) -> 294.3 | C15: 294.4 | D15: 295.8 | E15: 293 | F15: =IF([1]生データ_製品!$F2474="生産品",[1]生データ_製品!$D2474,NA()) -> #N/A | G15: 295.2 | H15: 296.64 | I15: 293.8 | J15: =IF([1]生データ_製品!$F5043="生産品",[1]生データ_製品!$D5043,NA()) -> 294.1 | K15: 294.2 | L15: 295.64 | M15: 292.8 | N15: =IF([1]生データ_製品!$F7512="生産品",[1]生データ_製品!$D7512,NA()) -> 295.9 | O15: 295.4 | P15: 296.8 | Q15: 294 | R15: =IF([1]生データ_製品!$F10126="生産品",[1]生データ_製品!$D10126,NA()) -> 292.9 | S15: 292.5 | T15: 293.9 | U15: 291.1 | V15: =IF([1]生データ_製品!$F12624="生産品",[1]生データ_製品!$D12624,NA()) -> #N/A | W15: 292.3 | X15: 293.7 | Y15: 290.9 | Z15: =IF([1]生データ_製品!$F15334="生産品",[1]生データ_製品!$D15334,NA()) -> #N/A | AA15: 294.2 | AB15: 295.6 | AC15: 292.8 | AD15: =IF([1]生データ_製品!$F17933="生産品",[1]生データ_製品!$D17933,NA()) -> 295.1 | AE15: 295.2 | AF15: 296.6 | AG15: 293.8 | AH15: =IF([1]生データ_製品!$F20526="生産品",[1]生データ_製品!$D20526,NA()) -> 294.8 | AI15: 295.8 | AJ15: 297.2 | AK15: 294.4 | AL15: =IF([1]生データ_製品!$F23074="生産品",[1]生データ_製品!$D23074,NA()) -> 291.9 | AM15: 292.5 | AN15: 293.9 | AO15: 291.1 | AP15: =IF([1]生データ_製品!$F25590="生産品",[1]生データ_製品!$D25590,NA()) -> 293.6 | AQ15: 294.1 | AR15: 295.5 | AS15: 292.7 | AT15: =IF([1]生データ_製品!$F28115="生産品",[1]生データ_製品!$D28115,NA()) -> 293.1 | AU15: 293 | AV15: 294.4 | AW15: 291.6 | AX15: =IF([1]生データ_製品!$F30766="生産品",[1]生データ_製品!$D30766,NA()) -> 295.4 | AY15: 293.8 | AZ15: 295.2 | BA15: 292.4 | BB15: =IF([1]生データ_製品!$F33263="生産品",[1]生データ_製品!$D33263,NA()) -> #N/A | BC15: 293.7 | BD15: 295.1 | BE15: 292.3 | BF15: =IF([1]生データ_製品!$F35716="生産品",[1]生データ_製品!$D35716,NA()) -> 293.9 | BG15: 293.6 | BH15: 295 | BI15: 292.2
A16: 12 | B16: =IF([1]生データ_製品!$F16="生産品",[1]生データ_製品!$D16,NA()) -> 294.6 | C16: 294.4 | D16: 295.8 | E16: 293 | F16: =IF([1]生データ_製品!$F2475="生産品",[1]生データ_製品!$D2475,NA()) -> 294.8 | G16: 295.2 | H16: 296.64 | I16: 293.8 | J16: =IF([1]生データ_製品!$F5044="生産品",[1]生データ_製品!$D5044,NA()) -> 294.3 | K16: 294.2 | L16: 295.64 | M16: 292.8 | N16: =IF([1]生データ_製品!$F7513="生産品",[1]生データ_製品!$D7513,NA()) -> 295.3 | O16: 295.4 | P16: 296.8 | Q16: 294 | R16: =IF([1]生データ_製品!$F10127="生産品",[1]生データ_製品!$D10127,NA()) -> 292.8 | S16: 292.5 | T16: 293.9 | U16: 291.1 | V16: =IF([1]生データ_製品!$F12625="生産品",[1]生データ_製品!$D12625,NA()) -> 292.3 | W16: 292.3 | X16: 293.7 | Y16: 290.9 | Z16: =IF([1]生データ_製品!$F15335="生産品",[1]生データ_製品!$D15335,NA()) -> 295.8 | AA16: 294.2 | AB16: 295.6 | AC16: 292.8 | AD16: =IF([1]生データ_製品!$F17934="生産品",[1]生データ_製品!$D17934,NA()) -> 295.1 | AE16: 295.2 | AF16: 296.6 | AG16: 293.8 | AH16: =IF([1]生データ_製品!$F20527="生産品",[1]生データ_製品!$D20527,NA()) -> 295.9 | AI16: 295.8 | AJ16: 297.2 | AK16: 294.4 | AL16: =IF([1]生データ_製品!$F23075="生産品",[1]生データ_製品!$D23075,NA()) -> 292.1 | AM16: 292.5 | AN16: 293.9 | AO16: 291.1 | AP16: =IF([1]生データ_製品!$F25591="生産品",[1]生データ_製品!$D25591,NA()) -> 294.2 | AQ16: 294.1 | AR16: 295.5 | AS16: 292.7 | AT16: =IF([1]生データ_製品!$F28116="生産品",[1]生データ_製品!$D28116,NA()) -> 293.4 | AU16: 293 | AV16: 294.4 | AW16: 291.6 | AX16: =IF([1]生データ_製品!$F30767="生産品",[1]生データ_製品!$D30767,NA()) -> 295 | AY16: 293.8 | AZ16: 295.2 | BA16: 292.4 | BB16: =IF([1]生データ_製品!$F33264="生産品",[1]生データ_製品!$D33264,NA()) -> 292.7 | BC16: 293.7 | BD16: 295.1 | BE16: 292.3 | BF16: =IF([1]生データ_製品!$F35717="生産品",[1]生データ_製品!$D35717,NA()) -> 293.7 | BG16: 293.6 | BH16: 295 | BI16: 292.2
... A2457: 2453 | B2457: =IF([1]生データ_製品!$F2457="生産品",[1]生データ_製品!$D2457,NA()) -> 295.5 | C2457: 294.4 | D2457: 295.8 | E2457: 293 | F2457: =IF([1]生データ_製品!$F4916="生産品",[1]生データ_製品!$D4916,NA()) -> 296.6 | G2457: 295.2 | H2457: 296.64 | I2457: 293.8 | J2457: =IF([1]生データ_製品!$F7485="生産品",[1]生データ_製品!$D7485,NA()) -> 294.7 | K2457: 294.2 | L2457: 295.64 | M2457: 292.8 | N2457: =IF([1]生データ_製品!$F9954="生産品",[1]生データ_製品!$D9954,NA()) -> 295.5 | O2457: 295.4 | P2457: 296.8 | Q2457: 294 | R2457: =IF([1]生データ_製品!$F12568="生産品",[1]生データ_製品!$D12568,NA()) -> 292.6 | S2457: 292.5 | T2457: 293.9 | U2457: 291.1 | V2457: =IF([1]生データ_製品!$F15066="生産品",[1]生データ_製品!$D15066,NA()) -> 294.1 | W2457: 292.3 | X2457: 293.7 | Y2457: 290.9 | Z2457: =IF([1]生データ_製品!$F17776="生産品",[1]生データ_製品!$D17776,NA()) -> 296 | AA2457: 294.2 | AB2457: 295.6 | AC2457: 292.8 | AD2457: =IF([1]生データ_製品!$F20375="生産品",[1]生データ_製品!$D20375,NA()) -> 294.6 | AE2457: 295.2 | AF2457: 296.6 | AG2457: 293.8 | AH2457: =IF([1]生データ_製品!$F22968="生産品",[1]生データ_製品!$D22968,NA()) -> 293 | AI2457: 295.8 | AJ2457: 297.2 | AK2457: 294.4 | AL2457: =IF([1]生データ_製品!$F25516="生産品",[1]生データ_製品!$D25516,NA()) -> 295.4 | AM2457: 292.5 | AN2457: 293.9 | AO2457: 291.1 | AP2457: =IF([1]生データ_製品!$F28032="生産品",[1]生データ_製品!$D28032,NA()) -> 293 | AQ2457: 294.1 | AR2457: 295.5 | AS2457: 292.7 | AT2457: =IF([1]生データ_製品!$F30557="生産品",[1]生データ_製品!$D30557,NA()) -> 295.5 | AU2457: 293 | AV2457: 294.4 | AW2457: 291.6 | AX2457: =IF([1]生データ_製品!$F33208="生産品",[1]生データ_製品!$D33208,NA()) -> 296.1 | AY2457: 293.8 | AZ2457: 295.2 | BA2457: 292.4 | BB2457: =IF([1]生データ_製品!$F35705="生産品",[1]生データ_製品!$D35705,NA()) -> 293.7 | BC2457: 293.7 | BD2457: 295.1 | BE2457: 292.3 | BF2457: =IF([1]生データ_製品!$F38158="生産品",[1]生データ_製品!$D38158,NA()) -> 294.4 | BG2457: 293.6 | BH2457: 295 | BI2457: 292.2
A2458: 2454 | B2458: =IF([1]生データ_製品!$F2458="生産品",[1]生データ_製品!$D2458,NA()) -> 294.9 | C2458: 294.4 | D2458: 295.8 | E2458: 293 | F2458: =IF([1]生データ_製品!$F4917="生産品",[1]生データ_製品!$D4917,NA()) -> 296.6 | G2458: 295.2 | H2458: 296.64 | I2458: 293.8 | J2458: =IF([1]生データ_製品!$F7486="生産品",[1]生データ_製品!$D7486,NA()) -> 294.8 | K2458: 294.2 | L2458: 295.64 | M2458: 292.8 | N2458: =IF([1]生データ_製品!$F9955="生産品",[1]生データ_製品!$D9955,NA()) -> 296 | O2458: 295.4 | P2458: 296.8 | Q2458: 294 | R2458: =IF([1]生データ_製品!$F12569="生産品",[1]生データ_製品!$D12569,NA()) -> 292.5 | S2458: 292.5 | T2458: 293.9 | U2458: 291.1 | V2458: =IF([1]生データ_製品!$F15067="生産品",[1]生データ_製品!$D15067,NA()) -> 295.6 | W2458: 292.3 | X2458: 293.7 | Y2458: 290.9 | Z2458: =IF([1]生データ_製品!$F17777="生産品",[1]生データ_製品!$D17777,NA()) -> 294.2 | AA2458: 294.2 | AB2458: 295.6 | AC2458: 292.8 | AD2458: =IF([1]生データ_製品!$F20376="生産品",[1]生データ_製品!$D20376,NA()) -> 294.4 | AE2458: 295.2 | AF2458: 296.6 | AG2458: 293.8 | AH2458: =IF([1]生データ_製品!$F22969="生産品",[1]生データ_製品!$D22969,NA()) -> 292.6 | AI2458: 295.8 | AJ2458: 297.2 | AK2458: 294.4 | AL2458: =IF([1]生データ_製品!$F25517="生産品",[1]生データ_製品!$D25517,NA()) -> 294 | AM2458: 292.5 | AN2458: 293.9 | AO2458: 291.1 | AP2458: =IF([1]生データ_製品!$F28033="生産品",[1]生データ_製品!$D28033,NA()) -> 293.5 | AQ2458: 294.1 | AR2458: 295.5 | AS2458: 292.7 | AT2458: =IF([1]生データ_製品!$F30558="生産品",[1]生データ_製品!$D30558,NA()) -> 294.3 | AU2458: 293 | AV2458: 294.4 | AW2458: 291.6 | AX2458: =IF([1]生データ_製品!$F33209="生産品",[1]生データ_製品!$D33209,NA()) -> 294.1 | AY2458: 293.8 | AZ2458: 295.2 | BA2458: 292.4 | BC2458: 293.7 | BD2458: 295.1 | BE2458: 292.3 | BF2458: =IF([1]生データ_製品!$F38159="生産品",[1]生データ_製品!$D38159,NA()) -> 294.5 | BG2458: 293.6 | BH2458: 295 | BI2458: 292.2
A2459: 2455 | B2459: =IF([1]生データ_製品!$F2459="生産品",[1]生データ_製品!$D2459,NA()) -> 295.1 | C2459: 294.4 | D2459: 295.8 | E2459: 293 | F2459: =IF([1]生データ_製品!$F4918="生産品",[1]生データ_製品!$D4918,NA()) -> 296.7 | G2459: 295.2 | H2459: 296.64 | I2459: 293.8 | J2459: =IF([1]生データ_製品!$F7487="生産品",[1]生データ_製品!$D7487,NA()) -> 294.5 | K2459: 294.2 | L2459: 295.64 | M2459: 292.8 | N2459: =IF([1]生データ_製品!$F9956="生産品",[1]生データ_製品!$D9956,NA()) -> 293.1 | O2459: 295.4 | P2459: 296.8 | Q2459: 294 | R2459: =IF([1]生データ_製品!$F12570="生産品",[1]生データ_製品!$D12570,NA()) -> 291.9 | S2459: 292.5 | T2459: 293.9 | U2459: 291.1 | V2459: =IF([1]生データ_製品!$F15068="生産品",[1]生データ_製品!$D15068,NA()) -> 292.4 | W2459: 292.3 | X2459: 293.7 | Y2459: 290.9 | Z2459: =IF([1]生データ_製品!$F17778="生産品",[1]生データ_製品!$D17778,NA()) -> 295.9 | AA2459: 294.2 | AB2459: 295.6 | AC2459: 292.8 | AD2459: =IF([1]生データ_製品!$F20377="生産品",[1]生データ_製品!$D20377,NA()) -> 295.3 | AE2459: 295.2 | AF2459: 296.6 | AG2459: 293.8 | AH2459: =IF([1]生データ_製品!$F22970="生産品",[1]生データ_製品!$D22970,NA()) -> 292.7 | AI2459: 295.8 | AJ2459: 297.2 | AK2459: 294.4 | AL2459: =IF([1]生データ_製品!$F25518="生産品",[1]生データ_製品!$D25518,NA()) -> 295 | AM2459: 292.5 | AN2459: 293.9 | AO2459: 291.1 | AP2459: =IF([1]生データ_製品!$F28034="生産品",[1]生データ_製品!$D28034,NA()) -> 293.4 | AQ2459: 294.1 | AR2459: 295.5 | AS2459: 292.7 | AT2459: =IF([1]生データ_製品!$F30559="生産品",[1]生データ_製品!$D30559,NA()) -> 293.2 | AU2459: 293 | AV2459: 294.4 | AW2459: 291.6 | AX2459: =IF([1]生データ_製品!$F33210="生産品",[1]生データ_製品!$D33210,NA()) -> 293 | AY2459: 293.8 | AZ2459: 295.2 | BA2459: 292.4 | BC2459: 293.7 | BD2459: 295.1 | BE2459: 292.3 | BF2459: =IF([1]生データ_製品!$F38160="生産品",[1]生データ_製品!$D38160,NA()) -> 295.4 | BG2459: 293.6 | BH2459: 295 | BI2459: 292.2
A2460: 2456 | B2460: =IF([1]生データ_製品!$F2460="生産品",[1]生データ_製品!$D2460,NA()) -> 295.3 | C2460: 294.4 | D2460: 295.8 | E2460: 293 | F2460: =IF([1]生データ_製品!$F4919="生産品",[1]生データ_製品!$D4919,NA()) -> 296.1 | G2460: 295.2 | H2460: 296.64 | I2460: 293.8 | J2460: =IF([1]生データ_製品!$F7488="生産品",[1]生データ_製品!$D7488,NA()) -> 294.6 | K2460: 294.2 | L2460: 295.64 | M2460: 292.8 | N2460: =IF([1]生データ_製品!$F9957="生産品",[1]生データ_製品!$D9957,NA()) -> 295.3 | O2460: 295.4 | P2460: 296.8 | Q2460: 294 | R2460: =IF([1]生データ_製品!$F12571="生産品",[1]生データ_製品!$D12571,NA()) -> 291.8 | S2460: 292.5 | T2460: 293.9 | U2460: 291.1 | V2460: =IF([1]生データ_製品!$F15069="生産品",[1]生データ_製品!$D15069,NA()) -> 295 | W2460: 292.3 | X2460: 293.7 | Y2460: 290.9 | Z2460: =IF([1]生データ_製品!$F17779="生産品",[1]生データ_製品!$D17779,NA()) -> 296.2 | AA2460: 294.2 | AB2460: 295.6 | AC2460: 292.8 | AD2460: =IF([1]生データ_製品!$F20378="生産品",[1]生データ_製品!$D20378,NA()) -> 294.5 | AE2460: 295.2 | AF2460: 296.6 | AG2460: 293.8 | AH2460: =IF([1]生データ_製品!$F22971="生産品",[1]生データ_製品!$D22971,NA()) -> 292.9 | AI2460: 295.8 | AJ2460: 297.2 | AK2460: 294.4 | AL2460: =IF([1]生データ_製品!$F25519="生産品",[1]生データ_製品!$D25519,NA()) -> 293.8 | AM2460: 292.5 | AN2460: 293.9 | AO2460: 291.1 | AP2460: =IF([1]生データ_製品!$F28035="生産品",[1]生データ_製品!$D28035,NA()) -> 293 | AQ2460: 294.1 | AR2460: 295.5 | AS2460: 292.7 | AT2460: =IF([1]生データ_製品!$F30560="生産品",[1]生データ_製品!$D30560,NA()) -> 293 | AU2460: 293 | AV2460: 294.4 | AW2460: 291.6 | AX2460: =IF([1]生データ_製品!$F33211="生産品",[1]生データ_製品!$D33211,NA()) -> 294.2 | AY2460: 293.8 | AZ2460: 295.2 | BA2460: 292.4 | BC2460: 293.7 | BD2460: 295.1 | BE2460: 292.3 | BF2460: =IF([1]生データ_製品!$F38161="生産品",[1]生データ_製品!$D38161,NA()) -> 294.3 | BG2460: 293.6 | BH2460: 295 | BI2460: 292.2
A2461: 2457 | B2461: =IF([1]生データ_製品!$F2461="生産品",[1]生データ_製品!$D2461,NA()) -> 294.4 | C2461: 294.4 | D2461: 295.8 | E2461: 293 | F2461: =IF([1]生データ_製品!$F4920="生産品",[1]生データ_製品!$D4920,NA()) -> #N/A | G2461: 295.2 | H2461: 296.64 | I2461: 293.8 | J2461: =IF([1]生データ_製品!$F7489="生産品",[1]生データ_製品!$D7489,NA()) -> 294.6 | K2461: 294.2 | L2461: 295.64 | M2461: 292.8 | N2461: =IF([1]生データ_製品!$F9958="生産品",[1]生データ_製品!$D9958,NA()) -> 295.8 | O2461: 295.4 | P2461: 296.8 | Q2461: 294 | R2461: =IF([1]生データ_製品!$F12572="生産品",[1]生データ_製品!$D12572,NA()) -> 291.9 | S2461: 292.5 | T2461: 293.9 | U2461: 291.1 | V2461: =IF([1]生データ_製品!$F15070="生産品",[1]生データ_製品!$D15070,NA()) -> 294.5 | W2461: 292.3 | X2461: 293.7 | Y2461: 290.9 | Z2461: =IF([1]生データ_製品!$F17780="生産品",[1]生データ_製品!$D17780,NA()) -> 295.9 | AA2461: 294.2 | AB2461: 295.6 | AC2461: 292.8 | AD2461: =IF([1]生データ_製品!$F20379="生産品",[1]生データ_製品!$D20379,NA()) -> 294.4 | AE2461: 295.2 | AF2461: 296.6 | AG2461: 293.8 | AH2461: =IF([1]生データ_製品!$F22972="生産品",[1]生データ_製品!$D22972,NA()) -> 293 | AI2461: 295.8 | AJ2461: 297.2 | AK2461: 294.4 | AL2461: =IF([1]生データ_製品!$F25520="生産品",[1]生データ_製品!$D25520,NA()) -> 293.7 | AM2461: 292.5 | AN2461: 293.9 | AO2461: 291.1 | AP2461: =IF([1]生データ_製品!$F28036="生産品",[1]生データ_製品!$D28036,NA()) -> 292.7 | AQ2461: 294.1 | AR2461: 295.5 | AS2461: 292.7 | AT2461: =IF([1]生データ_製品!$F30561="生産品",[1]生データ_製品!$D30561,NA()) -> 294.9 | AU2461: 293 | AV2461: 294.4 | AW2461: 291.6 | AX2461: =IF([1]生データ_製品!$F33212="生産品",[1]生データ_製品!$D33212,NA()) -> 293 | AY2461: 293.8 | AZ2461: 295.2 | BA2461: 292.4 | BC2461: 293.7 | BD2461: 295.1 | BE2461: 292.3 | BF2461: =IF([1]生データ_製品!$F38162="生産品",[1]生データ_製品!$D38162,NA()) -> 295 | BG2461: 293.6 | BH2461: 295 | BI2461: 292.2
A2462: 2458 | B2462: =IF([1]生データ_製品!$F2462="生産品",[1]生データ_製品!$D2462,NA()) -> 294.6 | C2462: 294.4 | D2462: 295.8 | E2462: 293 | F2462: =IF([1]生データ_製品!$F4921="生産品",[1]生データ_製品!$D4921,NA()) -> 296.5 | G2462: 295.2 | H2462: 296.64 | I2462: 293.8 | J2462: =IF([1]生データ_製品!$F7490="生産品",[1]生データ_製品!$D7490,NA()) -> 295 | K2462: 294.2 | L2462: 295.64 | M2462: 292.8 | N2462: =IF([1]生データ_製品!$F9959="生産品",[1]生データ_製品!$D9959,NA()) -> 295.6 | O2462: 295.4 | P2462: 296.8 | Q2462: 294 | R2462: =IF([1]生データ_製品!$F12573="生産品",[1]生データ_製品!$D12573,NA()) -> 293.3 | S2462: 292.5 | T2462: 293.9 | U2462: 291.1 | V2462: =IF([1]生データ_製品!$F15071="生産品",[1]生データ_製品!$D15071,NA()) -> 294.6 | W2462: 292.3 | X2462: 293.7 | Y2462: 290.9 | Z2462: =IF([1]生データ_製品!$F17781="生産品",[1]生データ_製品!$D17781,NA()) -> 296.1 | AA2462: 294.2 | AB2462: 295.6 | AC2462: 292.8 | AD2462: =IF([1]生データ_製品!$F20380="生産品",[1]生データ_製品!$D20380,NA()) -> 294.2 | AE2462: 295.2 | AF2462: 296.6 | AG2462: 293.8 | AH2462: =IF([1]生データ_製品!$F22973="生産品",[1]生データ_製品!$D22973,NA()) -> 292.1 | AI2462: 295.8 | AJ2462: 297.2 | AK2462: 294.4 | AL2462: =IF([1]生データ_製品!$F25521="生産品",[1]生データ_製品!$D25521,NA()) -> 293.8 | AM2462: 292.5 | AN2462: 293.9 | AO2462: 291.1 | AP2462: =IF([1]生データ_製品!$F28037="生産品",[1]生データ_製品!$D28037,NA()) -> 293 | AQ2462: 294.1 | AR2462: 295.5 | AS2462: 292.7 | AT2462: =IF([1]生データ_製品!$F30562="生産品",[1]生データ_製品!$D30562,NA()) -> 294.2 | AU2462: 293 | AV2462: 294.4 | AW2462: 291.6 | AX2462: =IF([1]生データ_製品!$F33213="生産品",[1]生データ_製品!$D33213,NA()) -> 293.5 | AY2462: 293.8 | AZ2462: 295.2 | BA2462: 292.4 | BC2462: 293.7 | BD2462: 295.1 | BE2462: 292.3 | BF2462: =IF([1]生データ_製品!$F38163="生産品",[1]生データ_製品!$D38163,NA()) -> 294.7 | BG2462: 293.6 | BH2462: 295 | BI2462: 292.2
A2463: 2459 | B2463: =IF([1]生データ_製品!$F2463="生産品",[1]生データ_製品!$D2463,NA()) -> 295.2 | C2463: 294.4 | D2463: 295.8 | E2463: 293 | F2463: =IF([1]生データ_製品!$F4922="生産品",[1]生データ_製品!$D4922,NA()) -> 296.6 | G2463: 295.2 | H2463: 296.64 | I2463: 293.8 | J2463: =IF([1]生データ_製品!$F7491="生産品",[1]生データ_製品!$D7491,NA()) -> 294.5 | K2463: 294.2 | L2463: 295.64 | M2463: 292.8 | N2463: =IF([1]生データ_製品!$F9960="生産品",[1]生データ_製品!$D9960,NA()) -> 295.3 | O2463: 295.4 | P2463: 296.8 | Q2463: 294 | R2463: =IF([1]生データ_製品!$F12574="生産品",[1]生データ_製品!$D12574,NA()) -> 292.6 | S2463: 292.5 | T2463: 293.9 | U2463: 291.1 | V2463: =IF([1]生データ_製品!$F15072="生産品",[1]生データ_製品!$D15072,NA()) -> 294.5 | W2463: 292.3 | X2463: 293.7 | Y2463: 290.9 | Z2463: =IF([1]生データ_製品!$F17782="生産品",[1]生データ_製品!$D17782,NA()) -> 295.1 | AA2463: 294.2 | AB2463: 295.6 | AC2463: 292.8 | AD2463: =IF([1]生データ_製品!$F20381="生産品",[1]生データ_製品!$D20381,NA()) -> 294.4 | AE2463: 295.2 | AF2463: 296.6 | AG2463: 293.8 | AH2463: =IF([1]生データ_製品!$F22974="生産品",[1]生データ_製品!$D22974,NA()) -> 292.3 | AI2463: 295.8 | AJ2463: 297.2 | AK2463: 294.4 | AL2463: =IF([1]生データ_製品!$F25522="生産品",[1]生データ_製品!$D25522,NA()) -> 294.1 | AM2463: 292.5 | AN2463: 293.9 | AO2463: 291.1 | AP2463: =IF([1]生データ_製品!$F28038="生産品",[1]生データ_製品!$D28038,NA()) -> 293 | AQ2463: 294.1 | AR2463: 295.5 | AS2463: 292.7 | AT2463: =IF([1]生データ_製品!$F30563="生産品",[1]生データ_製品!$D30563,NA()) -> 293.2 | AU2463: 293 | AV2463: 294.4 | AW2463: 291.6 | AX2463: =IF([1]生データ_製品!$F33214="生産品",[1]生データ_製品!$D33214,NA()) -> 293.2 | AY2463: 293.8 | AZ2463: 295.2 | BA2463: 292.4 | BC2463: 293.7 | BD2463: 295.1 | BE2463: 292.3 | BF2463: =IF([1]生データ_製品!$F38164="生産品",[1]生データ_製品!$D38164,NA()) -> 294.3 | BG2463: 293.6 | BH2463: 295 | BI2463: 292.2
A2464: 2460 | C2464: 294.4 | D2464: 295.8 | E2464: 293 | F2464: =IF([1]生データ_製品!$F4923="生産品",[1]生データ_製品!$D4923,NA()) -> 296.6 | G2464: 295.2 | H2464: 296.64 | I2464: 293.8 | J2464: =IF([1]生データ_製品!$F7492="生産品",[1]生データ_製品!$D7492,NA()) -> 294.6 | K2464: 294.2 | L2464: 295.64 | M2464: 292.8 | N2464: =IF([1]生データ_製品!$F9961="生産品",[1]生データ_製品!$D9961,NA()) -> 295 | O2464: 295.4 | P2464: 296.8 | Q2464: 294 | R2464: =IF([1]生データ_製品!$F12575="生産品",[1]生データ_製品!$D12575,NA()) -> 291.9 | S2464: 292.5 | T2464: 293.9 | U2464: 291.1 | V2464: =IF([1]生データ_製品!$F15073="生産品",[1]生データ_製品!$D15073,NA()) -> 294.5 | W2464: 292.3 | X2464: 293.7 | Y2464: 290.9 | Z2464: =IF([1]生データ_製品!$F17783="生産品",[1]生データ_製品!$D17783,NA()) -> 295.3 | AA2464: 294.2 | AB2464: 295.6 | AC2464: 292.8 | AD2464: =IF([1]生データ_製品!$F20382="生産品",[1]生データ_製品!$D20382,NA()) -> 294.9 | AE2464: 295.2 | AF2464: 296.6 | AG2464: 293.8 | AH2464: =IF([1]生データ_製品!$F22975="生産品",[1]生データ_製品!$D22975,NA()) -> 292.4 | AI2464: 295.8 | AJ2464: 297.2 | AK2464: 294.4 | AL2464: =IF([1]生データ_製品!$F25523="生産品",[1]生データ_製品!$D25523,NA()) -> 294.5 | AM2464: 292.5 | AN2464: 293.9 | AO2464: 291.1 | AP2464: =IF([1]生データ_製品!$F28039="生産品",[1]生データ_製品!$D28039,NA()) -> 293 | AQ2464: 294.1 | AR2464: 295.5 | AS2464: 292.7 | AT2464: =IF([1]生データ_製品!$F30564="生産品",[1]生データ_製品!$D30564,NA()) -> 294 | AU2464: 293 | AV2464: 294.4 | AW2464: 291.6 | AX2464: =IF([1]生データ_製品!$F33215="生産品",[1]生データ_製品!$D33215,NA()) -> 295 | AY2464: 293.8 | AZ2464: 295.2 | BA2464: 292.4 | BC2464: 293.7 | BD2464: 295.1 | BE2464: 292.3 | BF2464: =IF([1]生データ_製品!$F38165="生産品",[1]生データ_製品!$D38165,NA()) -> 294.4 | BG2464: 293.6 | BH2464: 295 | BI2464: 292.2
A2465: 2461 | C2465: 294.4 | D2465: 295.8 | E2465: 293 | F2465: =IF([1]生データ_製品!$F4924="生産品",[1]生データ_製品!$D4924,NA()) -> 296.5 | G2465: 295.2 | H2465: 296.64 | I2465: 293.8 | J2465: =IF([1]生データ_製品!$F7493="生産品",[1]生データ_製品!$D7493,NA()) -> 294.6 | K2465: 294.2 | L2465: 295.64 | M2465: 292.8 | N2465: =IF([1]生データ_製品!$F9962="生産品",[1]生データ_製品!$D9962,NA()) -> 295.4 | O2465: 295.4 | P2465: 296.8 | Q2465: 294 | R2465: =IF([1]生データ_製品!$F12576="生産品",[1]生データ_製品!$D12576,NA()) -> 292.2 | S2465: 292.5 | T2465: 293.9 | U2465: 291.1 | V2465: =IF([1]生データ_製品!$F15074="生産品",[1]生データ_製品!$D15074,NA()) -> 292.3 | W2465: 292.3 | X2465: 293.7 | Y2465: 290.9 | Z2465: =IF([1]生データ_製品!$F17784="生産品",[1]生データ_製品!$D17784,NA()) -> 295 | AA2465: 294.2 | AB2465: 295.6 | AC2465: 292.8 | AD2465: =IF([1]生データ_製品!$F20383="生産品",[1]生データ_製品!$D20383,NA()) -> 296.2 | AE2465: 295.2 | AF2465: 296.6 | AG2465: 293.8 | AH2465: =IF([1]生データ_製品!$F22976="生産品",[1]生データ_製品!$D22976,NA()) -> 291.6 | AI2465: 295.8 | AJ2465: 297.2 | AK2465: 294.4 | AL2465: =IF([1]生データ_製品!$F25524="生産品",[1]生データ_製品!$D25524,NA()) -> 295.1 | AM2465: 292.5 | AN2465: 293.9 | AO2465: 291.1 | AP2465: =IF([1]生データ_製品!$F28040="生産品",[1]生データ_製品!$D28040,NA()) -> 292.8 | AQ2465: 294.1 | AR2465: 295.5 | AS2465: 292.7 | AT2465: =IF([1]生データ_製品!$F30565="生産品",[1]生データ_製品!$D30565,NA()) -> 293.9 | AU2465: 293 | AV2465: 294.4 | AW2465: 291.6 | AX2465: =IF([1]生データ_製品!$F33216="生産品",[1]生データ_製品!$D33216,NA()) -> 293 | AY2465: 293.8 | AZ2465: 295.2 | BA2465: 292.4 | BC2465: 293.7 | BD2465: 295.1 | BE2465: 292.3 | BF2465: =IF([1]生データ_製品!$F38166="生産品",[1]生データ_製品!$D38166,NA()) -> 294.5 | BG2465: 293.6 | BH2465: 295 | BI2465: 292.2
A2466: 2462 | C2466: 294.4 | D2466: 295.8 | E2466: 293 | F2466: =IF([1]生データ_製品!$F4925="生産品",[1]生データ_製品!$D4925,NA()) -> 296.7 | G2466: 295.2 | H2466: 296.64 | I2466: 293.8 | J2466: =IF([1]生データ_製品!$F7494="生産品",[1]生データ_製品!$D7494,NA()) -> 294.8 | K2466: 294.2 | L2466: 295.64 | M2466: 292.8 | N2466: =IF([1]生データ_製品!$F9963="生産品",[1]生データ_製品!$D9963,NA()) -> 295.2 | O2466: 295.4 | P2466: 296.8 | Q2466: 294 | R2466: =IF([1]生データ_製品!$F12577="生産品",[1]生データ_製品!$D12577,NA()) -> 292.7 | S2466: 292.5 | T2466: 293.9 | U2466: 291.1 | V2466: =IF([1]生データ_製品!$F15075="生産品",[1]生データ_製品!$D15075,NA()) -> 292.5 | W2466: 292.3 | X2466: 293.7 | Y2466: 290.9 | Z2466: =IF([1]生データ_製品!$F17785="生産品",[1]生データ_製品!$D17785,NA()) -> 293.7 | AA2466: 294.2 | AB2466: 295.6 | AC2466: 292.8 | AD2466: =IF([1]生データ_製品!$F20384="生産品",[1]生データ_製品!$D20384,NA()) -> 295.2 | AE2466: 295.2 | AF2466: 296.6 | AG2466: 293.8 | AH2466: =IF([1]生データ_製品!$F22977="生産品",[1]生データ_製品!$D22977,NA()) -> 292.7 | AI2466: 295.8 | AJ2466: 297.2 | AK2466: 294.4 | AL2466: =IF([1]生データ_製品!$F25525="生産品",[1]生データ_製品!$D25525,NA()) -> 293.5 | AM2466: 292.5 | AN2466: 293.9 | AO2466: 291.1 | AP2466: =IF([1]生データ_製品!$F28041="生産品",[1]生データ_製品!$D28041,NA()) -> 292.5 | AQ2466: 294.1 | AR2466: 295.5 | AS2466: 292.7 | AT2466: =IF([1]生データ_製品!$F30566="生産品",[1]生データ_製品!$D30566,NA()) -> 293.1 | AU2466: 293 | AV2466: 294.4 | AW2466: 291.6 | AX2466: =IF([1]生データ_製品!$F33217="生産品",[1]生データ_製品!$D33217,NA()) -> 293 | AY2466: 293.8 | AZ2466: 295.2 | BA2466: 292.4 | BC2466: 293.7 | BD2466: 295.1 | BE2466: 292.3 | BF2466: =IF([1]生データ_製品!$F38167="生産品",[1]生データ_製品!$D38167,NA()) -> 294.4 | BG2466: 293.6 | BH2466: 295 | BI2466: 292.2
A2467: 2463 | C2467: 294.4 | D2467: 295.8 | E2467: 293 | F2467: =IF([1]生データ_製品!$F4926="生産品",[1]生データ_製品!$D4926,NA()) -> 296.6 | G2467: 295.2 | H2467: 296.64 | I2467: 293.8 | J2467: =IF([1]生データ_製品!$F7495="生産品",[1]生データ_製品!$D7495,NA()) -> 294.8 | K2467: 294.2 | L2467: 295.64 | M2467: 292.8 | N2467: =IF([1]生データ_製品!$F9964="生産品",[1]生データ_製品!$D9964,NA()) -> 295.9 | O2467: 295.4 | P2467: 296.8 | Q2467: 294 | R2467: =IF([1]生データ_製品!$F12578="生産品",[1]生データ_製品!$D12578,NA()) -> 293.3 | S2467: 292.5 | T2467: 293.9 | U2467: 291.1 | V2467: =IF([1]生データ_製品!$F15076="生産品",[1]生データ_製品!$D15076,NA()) -> 295.1 | W2467: 292.3 | X2467: 293.7 | Y2467: 290.9 | Z2467: =IF([1]生データ_製品!$F17786="生産品",[1]生データ_製品!$D17786,NA()) -> 295.5 | AA2467: 294.2 | AB2467: 295.6 | AC2467: 292.8 | AD2467: =IF([1]生データ_製品!$F20385="生産品",[1]生データ_製品!$D20385,NA()) -> 296.1 | AE2467: 295.2 | AF2467: 296.6 | AG2467: 293.8 | AH2467: =IF([1]生データ_製品!$F22978="生産品",[1]生データ_製品!$D22978,NA()) -> 292.5 | AI2467: 295.8 | AJ2467: 297.2 | AK2467: 294.4 | AL2467: =IF([1]生データ_製品!$F25526="生産品",[1]生データ_製品!$D25526,NA()) -> 293.6 | AM2467: 292.5 | AN2467: 293.9 | AO2467: 291.1 | AP2467: =IF([1]生データ_製品!$F28042="生産品",[1]生データ_製品!$D28042,NA()) -> 292.4 | AQ2467: 294.1 | AR2467: 295.5 | AS2467: 292.7 | AT2467: =IF([1]生データ_製品!$F30567="生産品",[1]生データ_製品!$D30567,NA()) -> 295.1 | AU2467: 293 | AV2467: 294.4 | AW2467: 291.6 | AX2467: =IF([1]生データ_製品!$F33218="生産品",[1]生データ_製品!$D33218,NA()) -> 293.6 | AY2467: 293.8 | AZ2467: 295.2 | BA2467: 292.4 | BC2467: 293.7 | BD2467: 295.1 | BE2467: 292.3 | BF2467: =IF([1]生データ_製品!$F38168="生産品",[1]生データ_製品!$D38168,NA()) -> 294.3 | BG2467: 293.6 | BH2467: 295 | BI2467: 292.2
A2468: 2464 | C2468: 294.4 | D2468: 295.8 | E2468: 293 | F2468: =IF([1]生データ_製品!$F4927="生産品",[1]生データ_製品!$D4927,NA()) -> 294.1 | G2468: 295.2 | H2468: 296.64 | I2468: 293.8 | J2468: =IF([1]生データ_製品!$F7496="生産品",[1]生データ_製品!$D7496,NA()) -> 294.8 | K2468: 294.2 | L2468: 295.64 | M2468: 292.8 | N2468: =IF([1]生データ_製品!$F9965="生産品",[1]生データ_製品!$D9965,NA()) -> 295.2 | O2468: 295.4 | P2468: 296.8 | Q2468: 294 | R2468: =IF([1]生データ_製品!$F12579="生産品",[1]生データ_製品!$D12579,NA()) -> 293.3 | S2468: 292.5 | T2468: 293.9 | U2468: 291.1 | V2468: =IF([1]生データ_製品!$F15077="生産品",[1]生データ_製品!$D15077,NA()) -> 292.8 | W2468: 292.3 | X2468: 293.7 | Y2468: 290.9 | Z2468: =IF([1]生データ_製品!$F17787="生産品",[1]生データ_製品!$D17787,NA()) -> 295.9 | AA2468: 294.2 | AB2468: 295.6 | AC2468: 292.8 | AD2468: =IF([1]生データ_製品!$F20386="生産品",[1]生データ_製品!$D20386,NA()) -> 296.1 | AE2468: 295.2 | AF2468: 296.6 | AG2468: 293.8 | AH2468: =IF([1]生データ_製品!$F22979="生産品",[1]生データ_製品!$D22979,NA()) -> 292.6 | AI2468: 295.8 | AJ2468: 297.2 | AK2468: 294.4 | AL2468: =IF([1]生データ_製品!$F25527="生産品",[1]生データ_製品!$D25527,NA()) -> 293.7 | AM2468: 292.5 | AN2468: 293.9 | AO2468: 291.1 | AP2468: =IF([1]生データ_製品!$F28043="生産品",[1]生データ_製品!$D28043,NA()) -> 292.6 | AQ2468: 294.1 | AR2468: 295.5 | AS2468: 292.7 | AT2468: =IF([1]生データ_製品!$F30568="生産品",[1]生データ_製品!$D30568,NA()) -> 293 | AU2468: 293 | AV2468: 294.4 | AW2468: 291.6 | AX2468: =IF([1]生データ_製品!$F33219="生産品",[1]生データ_製品!$D33219,NA()) -> 294.4 | AY2468: 293.8 | AZ2468: 295.2 | BA2468: 292.4 | BC2468: 293.7 | BD2468: 295.1 | BE2468: 292.3 | BF2468: =IF([1]生データ_製品!$F38169="生産品",[1]生データ_製品!$D38169,NA()) -> 292.8 | BG2468: 293.6 | BH2468: 295 | BI2468: 292.2
A2469: 2465 | C2469: 294.4 | D2469: 295.8 | E2469: 293 | F2469: =IF([1]生データ_製品!$F4928="生産品",[1]生データ_製品!$D4928,NA()) -> 293.9 | G2469: 295.2 | H2469: 296.64 | I2469: 293.8 | J2469: =IF([1]生データ_製品!$F7497="生産品",[1]生データ_製品!$D7497,NA()) -> 294.6 | K2469: 294.2 | L2469: 295.64 | M2469: 292.8 | N2469: =IF([1]生データ_製品!$F9966="生産品",[1]生データ_製品!$D9966,NA()) -> 296 | O2469: 295.4 | P2469: 296.8 | Q2469: 294 | R2469: =IF([1]生データ_製品!$F12580="生産品",[1]生データ_製品!$D12580,NA()) -> 292.4 | S2469: 292.5 | T2469: 293.9 | U2469: 291.1 | V2469: =IF([1]生データ_製品!$F15078="生産品",[1]生データ_製品!$D15078,NA()) -> 292.3 | W2469: 292.3 | X2469: 293.7 | Y2469: 290.9 | Z2469: =IF([1]生データ_製品!$F17788="生産品",[1]生データ_製品!$D17788,NA()) -> 293.5 | AA2469: 294.2 | AB2469: 295.6 | AC2469: 292.8 | AD2469: =IF([1]生データ_製品!$F20387="生産品",[1]生データ_製品!$D20387,NA()) -> 295.2 | AE2469: 295.2 | AF2469: 296.6 | AG2469: 293.8 | AH2469: =IF([1]生データ_製品!$F22980="生産品",[1]生データ_製品!$D22980,NA()) -> 292.6 | AI2469: 295.8 | AJ2469: 297.2 | AK2469: 294.4 | AL2469: =IF([1]生データ_製品!$F25528="生産品",[1]生データ_製品!$D25528,NA()) -> 294.8 | AM2469: 292.5 | AN2469: 293.9 | AO2469: 291.1 | AP2469: =IF([1]生データ_製品!$F28044="生産品",[1]生データ_製品!$D28044,NA()) -> 293.1 | AQ2469: 294.1 | AR2469: 295.5 | AS2469: 292.7 | AT2469: =IF([1]生データ_製品!$F30569="生産品",[1]生データ_製品!$D30569,NA()) -> 293.1 | AU2469: 293 | AV2469: 294.4 | AW2469: 291.6 | AX2469: =IF([1]生データ_製品!$F33220="生産品",[1]生データ_製品!$D33220,NA()) -> 293.4 | AY2469: 293.8 | AZ2469: 295.2 | BA2469: 292.4 | BC2469: 293.7 | BD2469: 295.1 | BE2469: 292.3 | BF2469: =IF([1]生データ_製品!$F38170="生産品",[1]生データ_製品!$D38170,NA()) -> 295 | BG2469: 293.6 | BH2469: 295 | BI2469: 292.2
A2470: 2466 | C2470: 294.4 | D2470: 295.8 | E2470: 293 | F2470: =IF([1]生データ_製品!$F4929="生産品",[1]生データ_製品!$D4929,NA()) -> 294 | G2470: 295.2 | H2470: 296.64 | I2470: 293.8 | J2470: =IF([1]生データ_製品!$F7498="生産品",[1]生データ_製品!$D7498,NA()) -> 294.6 | K2470: 294.2 | L2470: 295.64 | M2470: 292.8 | N2470: =IF([1]生データ_製品!$F9967="生産品",[1]生データ_製品!$D9967,NA()) -> 295.3 | O2470: 295.4 | P2470: 296.8 | Q2470: 294 | R2470: =IF([1]生データ_製品!$F12581="生産品",[1]生データ_製品!$D12581,NA()) -> 293.1 | S2470: 292.5 | T2470: 293.9 | U2470: 291.1 | V2470: =IF([1]生データ_製品!$F15079="生産品",[1]生データ_製品!$D15079,NA()) -> 292.5 | W2470: 292.3 | X2470: 293.7 | Y2470: 290.9 | Z2470: =IF([1]生データ_製品!$F17789="生産品",[1]生データ_製品!$D17789,NA()) -> 294.9 | AA2470: 294.2 | AB2470: 295.6 | AC2470: 292.8 | AD2470: =IF([1]生データ_製品!$F20388="生産品",[1]生データ_製品!$D20388,NA()) -> 295.8 | AE2470: 295.2 | AF2470: 296.6 | AG2470: 293.8 | AH2470: =IF([1]生データ_製品!$F22981="生産品",[1]生データ_製品!$D22981,NA()) -> 292.4 | AI2470: 295.8 | AJ2470: 297.2 | AK2470: 294.4 | AL2470: =IF([1]生データ_製品!$F25529="生産品",[1]生データ_製品!$D25529,NA()) -> 293.9 | AM2470: 292.5 | AN2470: 293.9 | AO2470: 291.1 | AP2470: =IF([1]生データ_製品!$F28045="生産品",[1]生データ_製品!$D28045,NA()) -> 292.7 | AQ2470: 294.1 | AR2470: 295.5 | AS2470: 292.7 | AT2470: =IF([1]生データ_製品!$F30570="生産品",[1]生データ_製品!$D30570,NA()) -> 294 | AU2470: 293 | AV2470: 294.4 | AW2470: 291.6 | AX2470: =IF([1]生データ_製品!$F33221="生産品",[1]生データ_製品!$D33221,NA()) -> 293.7 | AY2470: 293.8 | AZ2470: 295.2 | BA2470: 292.4 | BC2470: 293.7 | BD2470: 295.1 | BE2470: 292.3 | BF2470: =IF([1]生データ_製品!$F38171="生産品",[1]生データ_製品!$D38171,NA()) -> #N/A | BG2470: 293.6 | BH2470: 295 | BI2470: 292.2
A2471: 2467 | C2471: 294.4 | D2471: 295.8 | E2471: 293 | F2471: =IF([1]生データ_製品!$F4930="生産品",[1]生データ_製品!$D4930,NA()) -> 293.8 | G2471: 295.2 | H2471: 296.64 | I2471: 293.8 | J2471: =IF([1]生データ_製品!$F7499="生産品",[1]生データ_製品!$D7499,NA()) -> 294.4 | K2471: 294.2 | L2471: 295.64 | M2471: 292.8 | N2471: =IF([1]生データ_製品!$F9968="生産品",[1]生データ_製品!$D9968,NA()) -> 295.7 | O2471: 295.4 | P2471: 296.8 | Q2471: 294 | R2471: =IF([1]生データ_製品!$F12582="生産品",[1]生データ_製品!$D12582,NA()) -> 292.2 | S2471: 292.5 | T2471: 293.9 | U2471: 291.1 | V2471: =IF([1]生データ_製品!$F15080="生産品",[1]生データ_製品!$D15080,NA()) -> 292.5 | W2471: 292.3 | X2471: 293.7 | Y2471: 290.9 | Z2471: =IF([1]生データ_製品!$F17790="生産品",[1]生データ_製品!$D17790,NA()) -> 294.9 | AA2471: 294.2 | AB2471: 295.6 | AC2471: 292.8 | AD2471: =IF([1]生データ_製品!$F20389="生産品",[1]生データ_製品!$D20389,NA()) -> 295.3 | AE2471: 295.2 | AF2471: 296.6 | AG2471: 293.8 | AH2471: =IF([1]生データ_製品!$F22982="生産品",[1]生データ_製品!$D22982,NA()) -> 291.3 | AI2471: 295.8 | AJ2471: 297.2 | AK2471: 294.4 | AL2471: =IF([1]生データ_製品!$F25530="生産品",[1]生データ_製品!$D25530,NA()) -> 294.9 | AM2471: 292.5 | AN2471: 293.9 | AO2471: 291.1 | AP2471: =IF([1]生データ_製品!$F28046="生産品",[1]生データ_製品!$D28046,NA()) -> 292.7 | AQ2471: 294.1 | AR2471: 295.5 | AS2471: 292.7 | AT2471: =IF([1]生データ_製品!$F30571="生産品",[1]生データ_製品!$D30571,NA()) -> 294.8 | AU2471: 293 | AV2471: 294.4 | AW2471: 291.6 | AX2471: =IF([1]生データ_製品!$F33222="生産品",[1]生データ_製品!$D33222,NA()) -> 293.8 | AY2471: 293.8 | AZ2471: 295.2 | BA2471: 292.4 | BC2471: 293.7 | BD2471: 295.1 | BE2471: 292.3 | BF2471: =IF([1]生データ_製品!$F38172="生産品",[1]生データ_製品!$D38172,NA()) -> 294.9 | BG2471: 293.6 | BH2471: 295 | BI2471: 292.2
A2472: 2468 | C2472: 294.4 | D2472: 295.8 | E2472: 293 | F2472: =IF([1]生データ_製品!$F4931="生産品",[1]生データ_製品!$D4931,NA()) -> 293.7 | G2472: 295.2 | H2472: 296.64 | I2472: 293.8 | J2472: =IF([1]生データ_製品!$F7500="生産品",[1]生データ_製品!$D7500,NA()) -> 294.5 | K2472: 294.2 | L2472: 295.64 | M2472: 292.8 | N2472: =IF([1]生データ_製品!$F9969="生産品",[1]生データ_製品!$D9969,NA()) -> 295.2 | O2472: 295.4 | P2472: 296.8 | Q2472: 294 | R2472: =IF([1]生データ_製品!$F12583="生産品",[1]生データ_製品!$D12583,NA()) -> 292.2 | S2472: 292.5 | T2472: 293.9 | U2472: 291.1 | V2472: =IF([1]生データ_製品!$F15081="生産品",[1]生データ_製品!$D15081,NA()) -> 291.8 | W2472: 292.3 | X2472: 293.7 | Y2472: 290.9 | Z2472: =IF([1]生データ_製品!$F17791="生産品",[1]生データ_製品!$D17791,NA()) -> 294.3 | AA2472: 294.2 | AB2472: 295.6 | AC2472: 292.8 | AD2472: =IF([1]生データ_製品!$F20390="生産品",[1]生データ_製品!$D20390,NA()) -> 294.9 | AE2472: 295.2 | AF2472: 296.6 | AG2472: 293.8 | AH2472: =IF([1]生データ_製品!$F22983="生産品",[1]生データ_製品!$D22983,NA()) -> 292.1 | AI2472: 295.8 | AJ2472: 297.2 | AK2472: 294.4 | AL2472: =IF([1]生データ_製品!$F25531="生産品",[1]生データ_製品!$D25531,NA()) -> 292.7 | AM2472: 292.5 | AN2472: 293.9 | AO2472: 291.1 | AP2472: =IF([1]生データ_製品!$F28047="生産品",[1]生データ_製品!$D28047,NA()) -> 293.2 | AQ2472: 294.1 | AR2472: 295.5 | AS2472: 292.7 | AT2472: =IF([1]生データ_製品!$F30572="生産品",[1]生データ_製品!$D30572,NA()) -> 293 | AU2472: 293 | AV2472: 294.4 | AW2472: 291.6 | AX2472: =IF([1]生データ_製品!$F33223="生産品",[1]生データ_製品!$D33223,NA()) -> 294.6 | AY2472: 293.8 | AZ2472: 295.2 | BA2472: 292.4 | BC2472: 293.7 | BD2472: 295.1 | BE2472: 292.3 | BF2472: =IF([1]生データ_製品!$F38173="生産品",[1]生データ_製品!$D38173,NA()) -> 294.2 | BG2472: 293.6 | BH2472: 295 | BI2472: 292.2
A2473: 2469 | C2473: 294.4 | D2473: 295.8 | E2473: 293 | F2473: =IF([1]生データ_製品!$F4932="生産品",[1]生データ_製品!$D4932,NA()) -> 296.4 | G2473: 295.2 | H2473: 296.64 | I2473: 293.8 | J2473: =IF([1]生データ_製品!$F7501="生産品",[1]生データ_製品!$D7501,NA()) -> 294.2 | K2473: 294.2 | L2473: 295.64 | M2473: 292.8 | N2473: =IF([1]生データ_製品!$F9970="生産品",[1]生データ_製品!$D9970,NA()) -> 295.4 | O2473: 295.4 | P2473: 296.8 | Q2473: 294 | R2473: =IF([1]生データ_製品!$F12584="生産品",[1]生データ_製品!$D12584,NA()) -> 292 | S2473: 292.5 | T2473: 293.9 | U2473: 291.1 | V2473: =IF([1]生データ_製品!$F15082="生産品",[1]生データ_製品!$D15082,NA()) -> 292.7 | W2473: 292.3 | X2473: 293.7 | Y2473: 290.9 | Z2473: =IF([1]生データ_製品!$F17792="生産品",[1]生データ_製品!$D17792,NA()) -> 295.1 | AA2473: 294.2 | AB2473: 295.6 | AC2473: 292.8 | AD2473: =IF([1]生データ_製品!$F20391="生産品",[1]生データ_製品!$D20391,NA()) -> 295.1 | AE2473: 295.2 | AF2473: 296.6 | AG2473: 293.8 | AH2473: =IF([1]生データ_製品!$F22984="生産品",[1]生データ_製品!$D22984,NA()) -> 292.7 | AI2473: 295.8 | AJ2473: 297.2 | AK2473: 294.4 | AL2473: =IF([1]生データ_製品!$F25532="生産品",[1]生データ_製品!$D25532,NA()) -> 293.8 | AM2473: 292.5 | AN2473: 293.9 | AO2473: 291.1 | AP2473: =IF([1]生データ_製品!$F28048="生産品",[1]生データ_製品!$D28048,NA()) -> 293.2 | AQ2473: 294.1 | AR2473: 295.5 | AS2473: 292.7 | AT2473: =IF([1]生データ_製品!$F30573="生産品",[1]生データ_製品!$D30573,NA()) -> 291.9 | AU2473: 293 | AV2473: 294.4 | AW2473: 291.6 | AX2473: =IF([1]生データ_製品!$F33224="生産品",[1]生データ_製品!$D33224,NA()) -> 292.7 | AY2473: 293.8 | AZ2473: 295.2 | BA2473: 292.4 | BC2473: 293.7 | BD2473: 295.1 | BE2473: 292.3 | BF2473: =IF([1]生データ_製品!$F38174="生産品",[1]生データ_製品!$D38174,NA()) -> 293.5 | BG2473: 293.6 | BH2473: 295 | BI2473: 292.2
A2474: 2470 | C2474: 294.4 | D2474: 295.8 | E2474: 293 | F2474: =IF([1]生データ_製品!$F4933="生産品",[1]生データ_製品!$D4933,NA()) -> 294.1 | G2474: 295.2 | H2474: 296.64 | I2474: 293.8 | K2474: 294.2 | L2474: 295.64 | M2474: 292.8 | N2474: =IF([1]生データ_製品!$F9971="生産品",[1]生データ_製品!$D9971,NA()) -> 296.1 | O2474: 295.4 | P2474: 296.8 | Q2474: 294 | R2474: =IF([1]生データ_製品!$F12585="生産品",[1]生データ_製品!$D12585,NA()) -> 292 | S2474: 292.5 | T2474: 293.9 | U2474: 291.1 | V2474: =IF([1]生データ_製品!$F15083="生産品",[1]生データ_製品!$D15083,NA()) -> 292.3 | W2474: 292.3 | X2474: 293.7 | Y2474: 290.9 | Z2474: =IF([1]生データ_製品!$F17793="生産品",[1]生データ_製品!$D17793,NA()) -> 295.5 | AA2474: 294.2 | AB2474: 295.6 | AC2474: 292.8 | AD2474: =IF([1]生データ_製品!$F20392="生産品",[1]生データ_製品!$D20392,NA()) -> 294.9 | AE2474: 295.2 | AF2474: 296.6 | AG2474: 293.8 | AH2474: =IF([1]生データ_製品!$F22985="生産品",[1]生データ_製品!$D22985,NA()) -> 293.2 | AI2474: 295.8 | AJ2474: 297.2 | AK2474: 294.4 | AL2474: =IF([1]生データ_製品!$F25533="生産品",[1]生データ_製品!$D25533,NA()) -> 294.2 | AM2474: 292.5 | AN2474: 293.9 | AO2474: 291.1 | AP2474: =IF([1]生データ_製品!$F28049="生産品",[1]生データ_製品!$D28049,NA()) -> 293.1 | AQ2474: 294.1 | AR2474: 295.5 | AS2474: 292.7 | AT2474: =IF([1]生データ_製品!$F30574="生産品",[1]生データ_製品!$D30574,NA()) -> 293.9 | AU2474: 293 | AV2474: 294.4 | AW2474: 291.6 | AX2474: =IF([1]生データ_製品!$F33225="生産品",[1]生データ_製品!$D33225,NA()) -> 293 | AY2474: 293.8 | AZ2474: 295.2 | BA2474: 292.4 | BC2474: 293.7 | BD2474: 295.1 | BE2474: 292.3 | BF2474: =IF([1]生データ_製品!$F38175="生産品",[1]生データ_製品!$D38175,NA()) -> 294.7 | BG2474: 293.6 | BH2474: 295 | BI2474: 292.2
A2475: 2471 | C2475: 294.4 | D2475: 295.8 | E2475: 293 | F2475: =IF([1]生データ_製品!$F4934="生産品",[1]生データ_製品!$D4934,NA()) -> 296.9 | G2475: 295.2 | H2475: 296.64 | I2475: 293.8 | K2475: 294.2 | L2475: 295.64 | M2475: 292.8 | N2475: =IF([1]生データ_製品!$F9972="生産品",[1]生データ_製品!$D9972,NA()) -> 295.9 | O2475: 295.4 | P2475: 296.8 | Q2475: 294 | R2475: =IF([1]生データ_製品!$F12586="生産品",[1]生データ_製品!$D12586,NA()) -> 292.7 | S2475: 292.5 | T2475: 293.9 | U2475: 291.1 | V2475: =IF([1]生データ_製品!$F15084="生産品",[1]生データ_製品!$D15084,NA()) -> 292.7 | W2475: 292.3 | X2475: 293.7 | Y2475: 290.9 | Z2475: =IF([1]生データ_製品!$F17794="生産品",[1]生データ_製品!$D17794,NA()) -> 296.2 | AA2475: 294.2 | AB2475: 295.6 | AC2475: 292.8 | AD2475: =IF([1]生データ_製品!$F20393="生産品",[1]生データ_製品!$D20393,NA()) -> 294.5 | AE2475: 295.2 | AF2475: 296.6 | AG2475: 293.8 | AH2475: =IF([1]生データ_製品!$F22986="生産品",[1]生データ_製品!$D22986,NA()) -> 292.6 | AI2475: 295.8 | AJ2475: 297.2 | AK2475: 294.4 | AL2475: =IF([1]生データ_製品!$F25534="生産品",[1]生データ_製品!$D25534,NA()) -> 292.9 | AM2475: 292.5 | AN2475: 293.9 | AO2475: 291.1 | AP2475: =IF([1]生データ_製品!$F28050="生産品",[1]生データ_製品!$D28050,NA()) -> 293.2 | AQ2475: 294.1 | AR2475: 295.5 | AS2475: 292.7 | AT2475: =IF([1]生データ_製品!$F30575="生産品",[1]生データ_製品!$D30575,NA()) -> 294.8 | AU2475: 293 | AV2475: 294.4 | AW2475: 291.6 | AX2475: =IF([1]生データ_製品!$F33226="生産品",[1]生データ_製品!$D33226,NA()) -> 293 | AY2475: 293.8 | AZ2475: 295.2 | BA2475: 292.4 | BC2475: 293.7 | BD2475: 295.1 | BE2475: 292.3 | BF2475: =IF([1]生データ_製品!$F38176="生産品",[1]生データ_製品!$D38176,NA()) -> 293 | BG2475: 293.6 | BH2475: 295 | BI2475: 292.2
A2476: 2472 | C2476: 294.4 | D2476: 295.8 | E2476: 293 | F2476: =IF([1]生データ_製品!$F4935="生産品",[1]生データ_製品!$D4935,NA()) -> 293.9 | G2476: 295.2 | H2476: 296.64 | I2476: 293.8 | K2476: 294.2 | L2476: 295.64 | M2476: 292.8 | N2476: =IF([1]生データ_製品!$F9973="生産品",[1]生データ_製品!$D9973,NA()) -> 295.8 | O2476: 295.4 | P2476: 296.8 | Q2476: 294 | R2476: =IF([1]生データ_製品!$F12587="生産品",[1]生データ_製品!$D12587,NA()) -> 292.4 | S2476: 292.5 | T2476: 293.9 | U2476: 291.1 | V2476: =IF([1]生データ_製品!$F15085="生産品",[1]生データ_製品!$D15085,NA()) -> 291.9 | W2476: 292.3 | X2476: 293.7 | Y2476: 290.9 | Z2476: =IF([1]生データ_製品!$F17795="生産品",[1]生データ_製品!$D17795,NA()) -> 295.3 | AA2476: 294.2 | AB2476: 295.6 | AC2476: 292.8 | AD2476: =IF([1]生データ_製品!$F20394="生産品",[1]生データ_製品!$D20394,NA()) -> 295.6 | AE2476: 295.2 | AF2476: 296.6 | AG2476: 293.8 | AH2476: =IF([1]生データ_製品!$F22987="生産品",[1]生データ_製品!$D22987,NA()) -> 292.5 | AI2476: 295.8 | AJ2476: 297.2 | AK2476: 294.4 | AL2476: =IF([1]生データ_製品!$F25535="生産品",[1]生データ_製品!$D25535,NA()) -> 293.9 | AM2476: 292.5 | AN2476: 293.9 | AO2476: 291.1 | AP2476: =IF([1]生データ_製品!$F28051="生産品",[1]生データ_製品!$D28051,NA()) -> 293 | AQ2476: 294.1 | AR2476: 295.5 | AS2476: 292.7 | AT2476: =IF([1]生データ_製品!$F30576="生産品",[1]生データ_製品!$D30576,NA()) -> 294 | AU2476: 293 | AV2476: 294.4 | AW2476: 291.6 | AX2476: =IF([1]生データ_製品!$F33227="生産品",[1]生データ_製品!$D33227,NA()) -> 293.3 | AY2476: 293.8 | AZ2476: 295.2 | BA2476: 292.4 | BC2476: 293.7 | BD2476: 295.1 | BE2476: 292.3 | BF2476: =IF([1]生データ_製品!$F38177="生産品",[1]生データ_製品!$D38177,NA()) -> 294.9 | BG2476: 293.6 | BH2476: 295 | BI2476: 292.2
A2477: 2473 | C2477: 294.4 | D2477: 295.8 | E2477: 293 | F2477: =IF([1]生データ_製品!$F4936="生産品",[1]生データ_製品!$D4936,NA()) -> 296.7 | G2477: 295.2 | H2477: 296.64 | I2477: 293.8 | K2477: 294.2 | L2477: 295.64 | M2477: 292.8 | N2477: =IF([1]生データ_製品!$F9974="生産品",[1]生データ_製品!$D9974,NA()) -> 295.6 | O2477: 295.4 | P2477: 296.8 | Q2477: 294 | R2477: =IF([1]生データ_製品!$F12588="生産品",[1]生データ_製品!$D12588,NA()) -> 293.4 | S2477: 292.5 | T2477: 293.9 | U2477: 291.1 | V2477: =IF([1]生データ_製品!$F15086="生産品",[1]生データ_製品!$D15086,NA()) -> 291.6 | W2477: 292.3 | X2477: 293.7 | Y2477: 290.9 | Z2477: =IF([1]生データ_製品!$F17796="生産品",[1]生データ_製品!$D17796,NA()) -> 296.3 | AA2477: 294.2 | AB2477: 295.6 | AC2477: 292.8 | AD2477: =IF([1]生データ_製品!$F20395="生産品",[1]生データ_製品!$D20395,NA()) -> 295.5 | AE2477: 295.2 | AF2477: 296.6 | AG2477: 293.8 | AH2477: =IF([1]生データ_製品!$F22988="生産品",[1]生データ_製品!$D22988,NA()) -> 292.7 | AI2477: 295.8 | AJ2477: 297.2 | AK2477: 294.4 | AL2477: =IF([1]生データ_製品!$F25536="生産品",[1]生データ_製品!$D25536,NA()) -> 293.8 | AM2477: 292.5 | AN2477: 293.9 | AO2477: 291.1 | AP2477: =IF([1]生データ_製品!$F28052="生産品",[1]生データ_製品!$D28052,NA()) -> 293.6 | AQ2477: 294.1 | AR2477: 295.5 | AS2477: 292.7 | AT2477: =IF([1]生データ_製品!$F30577="生産品",[1]生データ_製品!$D30577,NA()) -> 293.9 | AU2477: 293 | AV2477: 294.4 | AW2477: 291.6 | AX2477: =IF([1]生データ_製品!$F33228="生産品",[1]生データ_製品!$D33228,NA()) -> 293.4 | AY2477: 293.8 | AZ2477: 295.2 | BA2477: 292.4 | BC2477: 293.7 | BD2477: 295.1 | BE2477: 292.3 | BF2477: =IF([1]生データ_製品!$F38178="生産品",[1]生データ_製品!$D38178,NA()) -> 292.8 | BG2477: 293.6 | BH2477: 295 | BI2477: 292.2
A2478: 2474 | C2478: 294.4 | D2478: 295.8 | E2478: 293 | F2478: =IF([1]生データ_製品!$F4937="生産品",[1]生データ_製品!$D4937,NA()) -> 296.2 | G2478: 295.2 | H2478: 296.64 | I2478: 293.8 | K2478: 294.2 | L2478: 295.64 | M2478: 292.8 | N2478: =IF([1]生データ_製品!$F9975="生産品",[1]生データ_製品!$D9975,NA()) -> 295.8 | O2478: 295.4 | P2478: 296.8 | Q2478: 294 | R2478: =IF([1]生データ_製品!$F12589="生産品",[1]生データ_製品!$D12589,NA()) -> 293.2 | S2478: 292.5 | T2478: 293.9 | U2478: 291.1 | V2478: =IF([1]生データ_製品!$F15087="生産品",[1]生データ_製品!$D15087,NA()) -> 294.2 | W2478: 292.3 | X2478: 293.7 | Y2478: 290.9 | Z2478: =IF([1]生データ_製品!$F17797="生産品",[1]生データ_製品!$D17797,NA()) -> 295.6 | AA2478: 294.2 | AB2478: 295.6 | AC2478: 292.8 | AD2478: =IF([1]生データ_製品!$F20396="生産品",[1]生データ_製品!$D20396,NA()) -> 294.8 | AE2478: 295.2 | AF2478: 296.6 | AG2478: 293.8 | AH2478: =IF([1]生データ_製品!$F22989="生産品",[1]生データ_製品!$D22989,NA()) -> 293 | AI2478: 295.8 | AJ2478: 297.2 | AK2478: 294.4 | AL2478: =IF([1]生データ_製品!$F25537="生産品",[1]生データ_製品!$D25537,NA()) -> 294.8 | AM2478: 292.5 | AN2478: 293.9 | AO2478: 291.1 | AP2478: =IF([1]生データ_製品!$F28053="生産品",[1]生データ_製品!$D28053,NA()) -> 292.9 | AQ2478: 294.1 | AR2478: 295.5 | AS2478: 292.7 | AT2478: =IF([1]生データ_製品!$F30578="生産品",[1]生データ_製品!$D30578,NA()) -> 295.2 | AU2478: 293 | AV2478: 294.4 | AW2478: 291.6 | AX2478: =IF([1]生データ_製品!$F33229="生産品",[1]生データ_製品!$D33229,NA()) -> 293.9 | AY2478: 293.8 | AZ2478: 295.2 | BA2478: 292.4 | BC2478: 293.7 | BD2478: 295.1 | BE2478: 292.3 | BG2478: 293.6 | BH2478: 295 | BI2478: 292.2
A2479: 2475 | C2479: 294.4 | D2479: 295.8 | E2479: 293 | F2479: =IF([1]生データ_製品!$F4938="生産品",[1]生データ_製品!$D4938,NA()) -> 296.7 | G2479: 295.2 | H2479: 296.64 | I2479: 293.8 | K2479: 294.2 | L2479: 295.64 | M2479: 292.8 | N2479: =IF([1]生データ_製品!$F9976="生産品",[1]生データ_製品!$D9976,NA()) -> 295.5 | O2479: 295.4 | P2479: 296.8 | Q2479: 294 | R2479: =IF([1]生データ_製品!$F12590="生産品",[1]生データ_製品!$D12590,NA()) -> 292.4 | S2479: 292.5 | T2479: 293.9 | U2479: 291.1 | V2479: =IF([1]生データ_製品!$F15088="生産品",[1]生データ_製品!$D15088,NA()) -> 292.6 | W2479: 292.3 | X2479: 293.7 | Y2479: 290.9 | Z2479: =IF([1]生データ_製品!$F17798="生産品",[1]生データ_製品!$D17798,NA()) -> 294.9 | AA2479: 294.2 | AB2479: 295.6 | AC2479: 292.8 | AD2479: =IF([1]生データ_製品!$F20397="生産品",[1]生データ_製品!$D20397,NA()) -> 294.7 | AE2479: 295.2 | AF2479: 296.6 | AG2479: 293.8 | AH2479: =IF([1]生データ_製品!$F22990="生産品",[1]生データ_製品!$D22990,NA()) -> 292.6 | AI2479: 295.8 | AJ2479: 297.2 | AK2479: 294.4 | AL2479: =IF([1]生データ_製品!$F25538="生産品",[1]生データ_製品!$D25538,NA()) -> 294.4 | AM2479: 292.5 | AN2479: 293.9 | AO2479: 291.1 | AP2479: =IF([1]生データ_製品!$F28054="生産品",[1]生データ_製品!$D28054,NA()) -> 293.1 | AQ2479: 294.1 | AR2479: 295.5 | AS2479: 292.7 | AT2479: =IF([1]生データ_製品!$F30579="生産品",[1]生データ_製品!$D30579,NA()) -> 293.1 | AU2479: 293 | AV2479: 294.4 | AW2479: 291.6 | AX2479: =IF([1]生データ_製品!$F33230="生産品",[1]生データ_製品!$D33230,NA()) -> 293.3 | AY2479: 293.8 | AZ2479: 295.2 | BA2479: 292.4 | BC2479: 293.7 | BD2479: 295.1 | BE2479: 292.3 | BG2479: 293.6 | BH2479: 295 | BI2479: 292.2
A2480: 2476 | C2480: 294.4 | D2480: 295.8 | E2480: 293 | F2480: =IF([1]生データ_製品!$F4939="生産品",[1]生データ_製品!$D4939,NA()) -> 296.2 | G2480: 295.2 | H2480: 296.64 | I2480: 293.8 | K2480: 294.2 | L2480: 295.64 | M2480: 292.8 | N2480: =IF([1]生データ_製品!$F9977="生産品",[1]生データ_製品!$D9977,NA()) -> 295.4 | O2480: 295.4 | P2480: 296.8 | Q2480: 294 | R2480: =IF([1]生データ_製品!$F12591="生産品",[1]生データ_製品!$D12591,NA()) -> 292.4 | S2480: 292.5 | T2480: 293.9 | U2480: 291.1 | V2480: =IF([1]生データ_製品!$F15089="生産品",[1]生データ_製品!$D15089,NA()) -> 294.4 | W2480: 292.3 | X2480: 293.7 | Y2480: 290.9 | Z2480: =IF([1]生データ_製品!$F17799="生産品",[1]生データ_製品!$D17799,NA()) -> 295.5 | AA2480: 294.2 | AB2480: 295.6 | AC2480: 292.8 | AD2480: =IF([1]生データ_製品!$F20398="生産品",[1]生データ_製品!$D20398,NA()) -> 295.2 | AE2480: 295.2 | AF2480: 296.6 | AG2480: 293.8 | AH2480: =IF([1]生データ_製品!$F22991="生産品",[1]生データ_製品!$D22991,NA()) -> 291.9 | AI2480: 295.8 | AJ2480: 297.2 | AK2480: 294.4 | AL2480: =IF([1]生データ_製品!$F25539="生産品",[1]生データ_製品!$D25539,NA()) -> 293.6 | AM2480: 292.5 | AN2480: 293.9 | AO2480: 291.1 | AP2480: =IF([1]生データ_製品!$F28055="生産品",[1]生データ_製品!$D28055,NA()) -> 293.2 | AQ2480: 294.1 | AR2480: 295.5 | AS2480: 292.7 | AT2480: =IF([1]生データ_製品!$F30580="生産品",[1]生データ_製品!$D30580,NA()) -> 295.3 | AU2480: 293 | AV2480: 294.4 | AW2480: 291.6 | AX2480: =IF([1]生データ_製品!$F33231="生産品",[1]生データ_製品!$D33231,NA()) -> 293.1 | AY2480: 293.8 | AZ2480: 295.2 | BA2480: 292.4 | BC2480: 293.7 | BD2480: 295.1 | BE2480: 292.3 | BG2480: 293.6 | BH2480: 295 | BI2480: 292.2
